2025-09-17 11:24:31,080 - __main__ - ERROR - Fatal startup error: Unknown format code 'd' for object of type 'float'
2025-09-17 11:24:31,080 - __main__ - ERROR - Detailed error information:
Traceback (most recent call last):
  File "E:\malek\Downloads\telegram_trading_bot_core\main.py", line 441, in run
    self._display_startup_info()
  File "E:\malek\Downloads\telegram_trading_bot_core\main.py", line 502, in _display_startup_info
    self.logger.info(f"   - Morning report: {config.get('MORNING_TIME', '09:00')} (UTC{config.get('TIMEZONE_OFFSET', 0):+d})")
                     ^^^^^^^^^^^^^^^^^^^^^^^^^^^^^^^^^^^^^^^^^^^^^^^^^^^^^^^^^^^^^^^^^^^^^^^^^^^^^^^^^^^^^^^^^^^^^^^^^^^^^^^^
ValueError: Unknown format code 'd' for object of type 'float'
2025-09-17 13:10:57,913 - bot - ERROR - Error during shutdown: 'Application' object has no attribute 'stop_running'
2025-09-17 13:41:02,026 - telegram.ext.Updater - ERROR - Error while getting Updates: httpx.ConnectError: 
2025-09-17 13:41:02,040 - telegram.ext.Application - ERROR - No error handlers are registered, logging exception.
Traceback (most recent call last):
  File "C:\Users\malek\AppData\Local\Programs\Python\Python311\Lib\site-packages\httpcore\_exceptions.py", line 10, in map_exceptions
    yield
  File "C:\Users\malek\AppData\Local\Programs\Python\Python311\Lib\site-packages\httpcore\_backends\anyio.py", line 78, in start_tls
    raise exc
  File "C:\Users\malek\AppData\Local\Programs\Python\Python311\Lib\site-packages\httpcore\_backends\anyio.py", line 69, in start_tls
    ssl_stream = await anyio.streams.tls.TLSStream.wrap(
                 ^^^^^^^^^^^^^^^^^^^^^^^^^^^^^^^^^^^^^^^
  File "C:\Users\malek\AppData\Local\Programs\Python\Python311\Lib\site-packages\anyio\streams\tls.py", line 165, in wrap
    await wrapper._call_sslobject_method(ssl_object.do_handshake)
  File "C:\Users\malek\AppData\Local\Programs\Python\Python311\Lib\site-packages\anyio\streams\tls.py", line 180, in _call_sslobject_method
    data = await self.transport_stream.receive()
           ^^^^^^^^^^^^^^^^^^^^^^^^^^^^^^^^^^^^^
  File "C:\Users\malek\AppData\Local\Programs\Python\Python311\Lib\site-packages\anyio\_backends\_asyncio.py", line 1265, in receive
    raise self._protocol.exception from None
anyio.BrokenResourceError

The above exception was the direct cause of the following exception:

Traceback (most recent call last):
  File "C:\Users\malek\AppData\Local\Programs\Python\Python311\Lib\site-packages\httpx\_transports\default.py", line 60, in map_httpcore_exceptions
    yield
  File "C:\Users\malek\AppData\Local\Programs\Python\Python311\Lib\site-packages\httpx\_transports\default.py", line 353, in handle_async_request
    resp = await self._pool.handle_async_request(req)
           ^^^^^^^^^^^^^^^^^^^^^^^^^^^^^^^^^^^^^^^^^^
  File "C:\Users\malek\AppData\Local\Programs\Python\Python311\Lib\site-packages\httpcore\_async\connection_pool.py", line 262, in handle_async_request
    raise exc
  File "C:\Users\malek\AppData\Local\Programs\Python\Python311\Lib\site-packages\httpcore\_async\connection_pool.py", line 245, in handle_async_request
    response = await connection.handle_async_request(request)
               ^^^^^^^^^^^^^^^^^^^^^^^^^^^^^^^^^^^^^^^^^^^^^^
  File "C:\Users\malek\AppData\Local\Programs\Python\Python311\Lib\site-packages\httpcore\_async\connection.py", line 92, in handle_async_request
    raise exc
  File "C:\Users\malek\AppData\Local\Programs\Python\Python311\Lib\site-packages\httpcore\_async\connection.py", line 69, in handle_async_request
    stream = await self._connect(request)
             ^^^^^^^^^^^^^^^^^^^^^^^^^^^^
  File "C:\Users\malek\AppData\Local\Programs\Python\Python311\Lib\site-packages\httpcore\_async\connection.py", line 149, in _connect
    stream = await stream.start_tls(**kwargs)
             ^^^^^^^^^^^^^^^^^^^^^^^^^^^^^^^^
  File "C:\Users\malek\AppData\Local\Programs\Python\Python311\Lib\site-packages\httpcore\_backends\anyio.py", line 66, in start_tls
    with map_exceptions(exc_map):
  File "C:\Users\malek\AppData\Local\Programs\Python\Python311\Lib\contextlib.py", line 155, in __exit__
    self.gen.throw(typ, value, traceback)
  File "C:\Users\malek\AppData\Local\Programs\Python\Python311\Lib\site-packages\httpcore\_exceptions.py", line 14, in map_exceptions
    raise to_exc(exc) from exc
httpcore.ConnectError

The above exception was the direct cause of the following exception:

Traceback (most recent call last):
  File "C:\Users\malek\AppData\Local\Programs\Python\Python311\Lib\site-packages\telegram\request\_httpxrequest.py", line 216, in do_request
    res = await self._client.request(
          ^^^^^^^^^^^^^^^^^^^^^^^^^^^
  File "C:\Users\malek\AppData\Local\Programs\Python\Python311\Lib\site-packages\httpx\_client.py", line 1530, in request
    return await self.send(request, auth=auth, follow_redirects=follow_redirects)
           ^^^^^^^^^^^^^^^^^^^^^^^^^^^^^^^^^^^^^^^^^^^^^^^^^^^^^^^^^^^^^^^^^^^^^^
  File "C:\Users\malek\AppData\Local\Programs\Python\Python311\Lib\site-packages\httpx\_client.py", line 1617, in send
    response = await self._send_handling_auth(
               ^^^^^^^^^^^^^^^^^^^^^^^^^^^^^^^
  File "C:\Users\malek\AppData\Local\Programs\Python\Python311\Lib\site-packages\httpx\_client.py", line 1645, in _send_handling_auth
    response = await self._send_handling_redirects(
               ^^^^^^^^^^^^^^^^^^^^^^^^^^^^^^^^^^^^
  File "C:\Users\malek\AppData\Local\Programs\Python\Python311\Lib\site-packages\httpx\_client.py", line 1682, in _send_handling_redirects
    response = await self._send_single_request(request)
               ^^^^^^^^^^^^^^^^^^^^^^^^^^^^^^^^^^^^^^^^
  File "C:\Users\malek\AppData\Local\Programs\Python\Python311\Lib\site-packages\httpx\_client.py", line 1719, in _send_single_request
    response = await transport.handle_async_request(request)
               ^^^^^^^^^^^^^^^^^^^^^^^^^^^^^^^^^^^^^^^^^^^^^
  File "C:\Users\malek\AppData\Local\Programs\Python\Python311\Lib\site-packages\httpx\_transports\default.py", line 352, in handle_async_request
    with map_httpcore_exceptions():
  File "C:\Users\malek\AppData\Local\Programs\Python\Python311\Lib\contextlib.py", line 155, in __exit__
    self.gen.throw(typ, value, traceback)
  File "C:\Users\malek\AppData\Local\Programs\Python\Python311\Lib\site-packages\httpx\_transports\default.py", line 77, in map_httpcore_exceptions
    raise mapped_exc(message) from exc
httpx.ConnectError

The above exception was the direct cause of the following exception:

Traceback (most recent call last):
  File "C:\Users\malek\AppData\Local\Programs\Python\Python311\Lib\site-packages\telegram\ext\_updater.py", line 607, in _network_loop_retry
    if not await action_cb():
           ^^^^^^^^^^^^^^^^^
  File "C:\Users\malek\AppData\Local\Programs\Python\Python311\Lib\site-packages\telegram\ext\_updater.py", line 335, in polling_action_cb
    raise exc
  File "C:\Users\malek\AppData\Local\Programs\Python\Python311\Lib\site-packages\telegram\ext\_updater.py", line 320, in polling_action_cb
    updates = await self.bot.get_updates(
              ^^^^^^^^^^^^^^^^^^^^^^^^^^^
  File "C:\Users\malek\AppData\Local\Programs\Python\Python311\Lib\site-packages\telegram\ext\_extbot.py", line 543, in get_updates
    updates = await super().get_updates(
              ^^^^^^^^^^^^^^^^^^^^^^^^^^
  File "C:\Users\malek\AppData\Local\Programs\Python\Python311\Lib\site-packages\telegram\_bot.py", line 381, in decorator
    result = await func(self, *args, **kwargs)  # skipcq: PYL-E1102
             ^^^^^^^^^^^^^^^^^^^^^^^^^^^^^^^^^
  File "C:\Users\malek\AppData\Local\Programs\Python\Python311\Lib\site-packages\telegram\_bot.py", line 3661, in get_updates
    await self._post(
  File "C:\Users\malek\AppData\Local\Programs\Python\Python311\Lib\site-packages\telegram\_bot.py", line 469, in _post
    return await self._do_post(
           ^^^^^^^^^^^^^^^^^^^^
  File "C:\Users\malek\AppData\Local\Programs\Python\Python311\Lib\site-packages\telegram\ext\_extbot.py", line 325, in _do_post
    return await super()._do_post(
           ^^^^^^^^^^^^^^^^^^^^^^^
  File "C:\Users\malek\AppData\Local\Programs\Python\Python311\Lib\site-packages\telegram\_bot.py", line 497, in _do_post
    return await request.post(
           ^^^^^^^^^^^^^^^^^^^
  File "C:\Users\malek\AppData\Local\Programs\Python\Python311\Lib\site-packages\telegram\request\_baserequest.py", line 168, in post
    result = await self._request_wrapper(
             ^^^^^^^^^^^^^^^^^^^^^^^^^^^^
  File "C:\Users\malek\AppData\Local\Programs\Python\Python311\Lib\site-packages\telegram\request\_baserequest.py", line 291, in _request_wrapper
    raise exc
  File "C:\Users\malek\AppData\Local\Programs\Python\Python311\Lib\site-packages\telegram\request\_baserequest.py", line 277, in _request_wrapper
    code, payload = await self.do_request(
                    ^^^^^^^^^^^^^^^^^^^^^^
  File "C:\Users\malek\AppData\Local\Programs\Python\Python311\Lib\site-packages\telegram\request\_httpxrequest.py", line 240, in do_request
    raise NetworkError(f"httpx.{err.__class__.__name__}: {err}") from err
telegram.error.NetworkError: httpx.ConnectError: 
2025-09-17 14:01:56,999 - telegram.ext.Updater - ERROR - Error while getting Updates: httpx.ConnectError: [Errno 11001] getaddrinfo failed
2025-09-17 14:01:57,005 - telegram.ext.Application - ERROR - No error handlers are registered, logging exception.
Traceback (most recent call last):
  File "C:\Users\malek\AppData\Local\Programs\Python\Python311\Lib\site-packages\httpcore\_exceptions.py", line 10, in map_exceptions
    yield
  File "C:\Users\malek\AppData\Local\Programs\Python\Python311\Lib\site-packages\httpcore\_backends\anyio.py", line 114, in connect_tcp
    stream: anyio.abc.ByteStream = await anyio.connect_tcp(
                                   ^^^^^^^^^^^^^^^^^^^^^^^^
  File "C:\Users\malek\AppData\Local\Programs\Python\Python311\Lib\site-packages\anyio\_core\_sockets.py", line 215, in connect_tcp
    gai_res = await getaddrinfo(
              ^^^^^^^^^^^^^^^^^^
  File "C:\Users\malek\AppData\Local\Programs\Python\Python311\Lib\site-packages\anyio\_core\_sockets.py", line 592, in getaddrinfo
    gai_res = await get_async_backend().getaddrinfo(
              ^^^^^^^^^^^^^^^^^^^^^^^^^^^^^^^^^^^^^^
  File "C:\Users\malek\AppData\Local\Programs\Python\Python311\Lib\site-packages\anyio\_backends\_asyncio.py", line 2698, in getaddrinfo
    return await get_running_loop().getaddrinfo(
           ^^^^^^^^^^^^^^^^^^^^^^^^^^^^^^^^^^^^^
  File "C:\Users\malek\AppData\Local\Programs\Python\Python311\Lib\asyncio\base_events.py", line 864, in getaddrinfo
    return await self.run_in_executor(
           ^^^^^^^^^^^^^^^^^^^^^^^^^^^
  File "C:\Users\malek\AppData\Local\Programs\Python\Python311\Lib\concurrent\futures\thread.py", line 58, in run
    result = self.fn(*self.args, **self.kwargs)
             ^^^^^^^^^^^^^^^^^^^^^^^^^^^^^^^^^^
  File "C:\Users\malek\AppData\Local\Programs\Python\Python311\Lib\socket.py", line 961, in getaddrinfo
    for res in _socket.getaddrinfo(host, port, family, type, proto, flags):
               ^^^^^^^^^^^^^^^^^^^^^^^^^^^^^^^^^^^^^^^^^^^^^^^^^^^^^^^^^^^
socket.gaierror: [Errno 11001] getaddrinfo failed

The above exception was the direct cause of the following exception:

Traceback (most recent call last):
  File "C:\Users\malek\AppData\Local\Programs\Python\Python311\Lib\site-packages\httpx\_transports\default.py", line 60, in map_httpcore_exceptions
    yield
  File "C:\Users\malek\AppData\Local\Programs\Python\Python311\Lib\site-packages\httpx\_transports\default.py", line 353, in handle_async_request
    resp = await self._pool.handle_async_request(req)
           ^^^^^^^^^^^^^^^^^^^^^^^^^^^^^^^^^^^^^^^^^^
  File "C:\Users\malek\AppData\Local\Programs\Python\Python311\Lib\site-packages\httpcore\_async\connection_pool.py", line 262, in handle_async_request
    raise exc
  File "C:\Users\malek\AppData\Local\Programs\Python\Python311\Lib\site-packages\httpcore\_async\connection_pool.py", line 245, in handle_async_request
    response = await connection.handle_async_request(request)
               ^^^^^^^^^^^^^^^^^^^^^^^^^^^^^^^^^^^^^^^^^^^^^^
  File "C:\Users\malek\AppData\Local\Programs\Python\Python311\Lib\site-packages\httpcore\_async\connection.py", line 92, in handle_async_request
    raise exc
  File "C:\Users\malek\AppData\Local\Programs\Python\Python311\Lib\site-packages\httpcore\_async\connection.py", line 69, in handle_async_request
    stream = await self._connect(request)
             ^^^^^^^^^^^^^^^^^^^^^^^^^^^^
  File "C:\Users\malek\AppData\Local\Programs\Python\Python311\Lib\site-packages\httpcore\_async\connection.py", line 117, in _connect
    stream = await self._network_backend.connect_tcp(**kwargs)
             ^^^^^^^^^^^^^^^^^^^^^^^^^^^^^^^^^^^^^^^^^^^^^^^^^
  File "C:\Users\malek\AppData\Local\Programs\Python\Python311\Lib\site-packages\httpcore\_backends\auto.py", line 31, in connect_tcp
    return await self._backend.connect_tcp(
           ^^^^^^^^^^^^^^^^^^^^^^^^^^^^^^^^
  File "C:\Users\malek\AppData\Local\Programs\Python\Python311\Lib\site-packages\httpcore\_backends\anyio.py", line 112, in connect_tcp
    with map_exceptions(exc_map):
  File "C:\Users\malek\AppData\Local\Programs\Python\Python311\Lib\contextlib.py", line 155, in __exit__
    self.gen.throw(typ, value, traceback)
  File "C:\Users\malek\AppData\Local\Programs\Python\Python311\Lib\site-packages\httpcore\_exceptions.py", line 14, in map_exceptions
    raise to_exc(exc) from exc
httpcore.ConnectError: [Errno 11001] getaddrinfo failed

The above exception was the direct cause of the following exception:

Traceback (most recent call last):
  File "C:\Users\malek\AppData\Local\Programs\Python\Python311\Lib\site-packages\telegram\request\_httpxrequest.py", line 216, in do_request
    res = await self._client.request(
          ^^^^^^^^^^^^^^^^^^^^^^^^^^^
  File "C:\Users\malek\AppData\Local\Programs\Python\Python311\Lib\site-packages\httpx\_client.py", line 1530, in request
    return await self.send(request, auth=auth, follow_redirects=follow_redirects)
           ^^^^^^^^^^^^^^^^^^^^^^^^^^^^^^^^^^^^^^^^^^^^^^^^^^^^^^^^^^^^^^^^^^^^^^
  File "C:\Users\malek\AppData\Local\Programs\Python\Python311\Lib\site-packages\httpx\_client.py", line 1617, in send
    response = await self._send_handling_auth(
               ^^^^^^^^^^^^^^^^^^^^^^^^^^^^^^^
  File "C:\Users\malek\AppData\Local\Programs\Python\Python311\Lib\site-packages\httpx\_client.py", line 1645, in _send_handling_auth
    response = await self._send_handling_redirects(
               ^^^^^^^^^^^^^^^^^^^^^^^^^^^^^^^^^^^^
  File "C:\Users\malek\AppData\Local\Programs\Python\Python311\Lib\site-packages\httpx\_client.py", line 1682, in _send_handling_redirects
    response = await self._send_single_request(request)
               ^^^^^^^^^^^^^^^^^^^^^^^^^^^^^^^^^^^^^^^^
  File "C:\Users\malek\AppData\Local\Programs\Python\Python311\Lib\site-packages\httpx\_client.py", line 1719, in _send_single_request
    response = await transport.handle_async_request(request)
               ^^^^^^^^^^^^^^^^^^^^^^^^^^^^^^^^^^^^^^^^^^^^^
  File "C:\Users\malek\AppData\Local\Programs\Python\Python311\Lib\site-packages\httpx\_transports\default.py", line 352, in handle_async_request
    with map_httpcore_exceptions():
  File "C:\Users\malek\AppData\Local\Programs\Python\Python311\Lib\contextlib.py", line 155, in __exit__
    self.gen.throw(typ, value, traceback)
  File "C:\Users\malek\AppData\Local\Programs\Python\Python311\Lib\site-packages\httpx\_transports\default.py", line 77, in map_httpcore_exceptions
    raise mapped_exc(message) from exc
httpx.ConnectError: [Errno 11001] getaddrinfo failed

The above exception was the direct cause of the following exception:

Traceback (most recent call last):
  File "C:\Users\malek\AppData\Local\Programs\Python\Python311\Lib\site-packages\telegram\ext\_updater.py", line 607, in _network_loop_retry
    if not await action_cb():
           ^^^^^^^^^^^^^^^^^
  File "C:\Users\malek\AppData\Local\Programs\Python\Python311\Lib\site-packages\telegram\ext\_updater.py", line 335, in polling_action_cb
    raise exc
  File "C:\Users\malek\AppData\Local\Programs\Python\Python311\Lib\site-packages\telegram\ext\_updater.py", line 320, in polling_action_cb
    updates = await self.bot.get_updates(
              ^^^^^^^^^^^^^^^^^^^^^^^^^^^
  File "C:\Users\malek\AppData\Local\Programs\Python\Python311\Lib\site-packages\telegram\ext\_extbot.py", line 543, in get_updates
    updates = await super().get_updates(
              ^^^^^^^^^^^^^^^^^^^^^^^^^^
  File "C:\Users\malek\AppData\Local\Programs\Python\Python311\Lib\site-packages\telegram\_bot.py", line 381, in decorator
    result = await func(self, *args, **kwargs)  # skipcq: PYL-E1102
             ^^^^^^^^^^^^^^^^^^^^^^^^^^^^^^^^^
  File "C:\Users\malek\AppData\Local\Programs\Python\Python311\Lib\site-packages\telegram\_bot.py", line 3661, in get_updates
    await self._post(
  File "C:\Users\malek\AppData\Local\Programs\Python\Python311\Lib\site-packages\telegram\_bot.py", line 469, in _post
    return await self._do_post(
           ^^^^^^^^^^^^^^^^^^^^
  File "C:\Users\malek\AppData\Local\Programs\Python\Python311\Lib\site-packages\telegram\ext\_extbot.py", line 325, in _do_post
    return await super()._do_post(
           ^^^^^^^^^^^^^^^^^^^^^^^
  File "C:\Users\malek\AppData\Local\Programs\Python\Python311\Lib\site-packages\telegram\_bot.py", line 497, in _do_post
    return await request.post(
           ^^^^^^^^^^^^^^^^^^^
  File "C:\Users\malek\AppData\Local\Programs\Python\Python311\Lib\site-packages\telegram\request\_baserequest.py", line 168, in post
    result = await self._request_wrapper(
             ^^^^^^^^^^^^^^^^^^^^^^^^^^^^
  File "C:\Users\malek\AppData\Local\Programs\Python\Python311\Lib\site-packages\telegram\request\_baserequest.py", line 291, in _request_wrapper
    raise exc
  File "C:\Users\malek\AppData\Local\Programs\Python\Python311\Lib\site-packages\telegram\request\_baserequest.py", line 277, in _request_wrapper
    code, payload = await self.do_request(
                    ^^^^^^^^^^^^^^^^^^^^^^
  File "C:\Users\malek\AppData\Local\Programs\Python\Python311\Lib\site-packages\telegram\request\_httpxrequest.py", line 240, in do_request
    raise NetworkError(f"httpx.{err.__class__.__name__}: {err}") from err
telegram.error.NetworkError: httpx.ConnectError: [Errno 11001] getaddrinfo failed
2025-09-17 14:02:09,269 - telegram.ext.Updater - ERROR - Error while getting Updates: httpx.ConnectError: [Errno 11001] getaddrinfo failed
2025-09-17 14:02:09,271 - telegram.ext.Application - ERROR - No error handlers are registered, logging exception.
Traceback (most recent call last):
  File "C:\Users\malek\AppData\Local\Programs\Python\Python311\Lib\site-packages\httpcore\_exceptions.py", line 10, in map_exceptions
    yield
  File "C:\Users\malek\AppData\Local\Programs\Python\Python311\Lib\site-packages\httpcore\_backends\anyio.py", line 114, in connect_tcp
    stream: anyio.abc.ByteStream = await anyio.connect_tcp(
                                   ^^^^^^^^^^^^^^^^^^^^^^^^
  File "C:\Users\malek\AppData\Local\Programs\Python\Python311\Lib\site-packages\anyio\_core\_sockets.py", line 215, in connect_tcp
    gai_res = await getaddrinfo(
              ^^^^^^^^^^^^^^^^^^
  File "C:\Users\malek\AppData\Local\Programs\Python\Python311\Lib\site-packages\anyio\_core\_sockets.py", line 592, in getaddrinfo
    gai_res = await get_async_backend().getaddrinfo(
              ^^^^^^^^^^^^^^^^^^^^^^^^^^^^^^^^^^^^^^
  File "C:\Users\malek\AppData\Local\Programs\Python\Python311\Lib\site-packages\anyio\_backends\_asyncio.py", line 2698, in getaddrinfo
    return await get_running_loop().getaddrinfo(
           ^^^^^^^^^^^^^^^^^^^^^^^^^^^^^^^^^^^^^
  File "C:\Users\malek\AppData\Local\Programs\Python\Python311\Lib\asyncio\base_events.py", line 864, in getaddrinfo
    return await self.run_in_executor(
           ^^^^^^^^^^^^^^^^^^^^^^^^^^^
  File "C:\Users\malek\AppData\Local\Programs\Python\Python311\Lib\concurrent\futures\thread.py", line 58, in run
    result = self.fn(*self.args, **self.kwargs)
             ^^^^^^^^^^^^^^^^^^^^^^^^^^^^^^^^^^
  File "C:\Users\malek\AppData\Local\Programs\Python\Python311\Lib\socket.py", line 961, in getaddrinfo
    for res in _socket.getaddrinfo(host, port, family, type, proto, flags):
               ^^^^^^^^^^^^^^^^^^^^^^^^^^^^^^^^^^^^^^^^^^^^^^^^^^^^^^^^^^^
socket.gaierror: [Errno 11001] getaddrinfo failed

The above exception was the direct cause of the following exception:

Traceback (most recent call last):
  File "C:\Users\malek\AppData\Local\Programs\Python\Python311\Lib\site-packages\httpx\_transports\default.py", line 60, in map_httpcore_exceptions
    yield
  File "C:\Users\malek\AppData\Local\Programs\Python\Python311\Lib\site-packages\httpx\_transports\default.py", line 353, in handle_async_request
    resp = await self._pool.handle_async_request(req)
           ^^^^^^^^^^^^^^^^^^^^^^^^^^^^^^^^^^^^^^^^^^
  File "C:\Users\malek\AppData\Local\Programs\Python\Python311\Lib\site-packages\httpcore\_async\connection_pool.py", line 262, in handle_async_request
    raise exc
  File "C:\Users\malek\AppData\Local\Programs\Python\Python311\Lib\site-packages\httpcore\_async\connection_pool.py", line 245, in handle_async_request
    response = await connection.handle_async_request(request)
               ^^^^^^^^^^^^^^^^^^^^^^^^^^^^^^^^^^^^^^^^^^^^^^
  File "C:\Users\malek\AppData\Local\Programs\Python\Python311\Lib\site-packages\httpcore\_async\connection.py", line 92, in handle_async_request
    raise exc
  File "C:\Users\malek\AppData\Local\Programs\Python\Python311\Lib\site-packages\httpcore\_async\connection.py", line 69, in handle_async_request
    stream = await self._connect(request)
             ^^^^^^^^^^^^^^^^^^^^^^^^^^^^
  File "C:\Users\malek\AppData\Local\Programs\Python\Python311\Lib\site-packages\httpcore\_async\connection.py", line 117, in _connect
    stream = await self._network_backend.connect_tcp(**kwargs)
             ^^^^^^^^^^^^^^^^^^^^^^^^^^^^^^^^^^^^^^^^^^^^^^^^^
  File "C:\Users\malek\AppData\Local\Programs\Python\Python311\Lib\site-packages\httpcore\_backends\auto.py", line 31, in connect_tcp
    return await self._backend.connect_tcp(
           ^^^^^^^^^^^^^^^^^^^^^^^^^^^^^^^^
  File "C:\Users\malek\AppData\Local\Programs\Python\Python311\Lib\site-packages\httpcore\_backends\anyio.py", line 112, in connect_tcp
    with map_exceptions(exc_map):
  File "C:\Users\malek\AppData\Local\Programs\Python\Python311\Lib\contextlib.py", line 155, in __exit__
    self.gen.throw(typ, value, traceback)
  File "C:\Users\malek\AppData\Local\Programs\Python\Python311\Lib\site-packages\httpcore\_exceptions.py", line 14, in map_exceptions
    raise to_exc(exc) from exc
httpcore.ConnectError: [Errno 11001] getaddrinfo failed

The above exception was the direct cause of the following exception:

Traceback (most recent call last):
  File "C:\Users\malek\AppData\Local\Programs\Python\Python311\Lib\site-packages\telegram\request\_httpxrequest.py", line 216, in do_request
    res = await self._client.request(
          ^^^^^^^^^^^^^^^^^^^^^^^^^^^
  File "C:\Users\malek\AppData\Local\Programs\Python\Python311\Lib\site-packages\httpx\_client.py", line 1530, in request
    return await self.send(request, auth=auth, follow_redirects=follow_redirects)
           ^^^^^^^^^^^^^^^^^^^^^^^^^^^^^^^^^^^^^^^^^^^^^^^^^^^^^^^^^^^^^^^^^^^^^^
  File "C:\Users\malek\AppData\Local\Programs\Python\Python311\Lib\site-packages\httpx\_client.py", line 1617, in send
    response = await self._send_handling_auth(
               ^^^^^^^^^^^^^^^^^^^^^^^^^^^^^^^
  File "C:\Users\malek\AppData\Local\Programs\Python\Python311\Lib\site-packages\httpx\_client.py", line 1645, in _send_handling_auth
    response = await self._send_handling_redirects(
               ^^^^^^^^^^^^^^^^^^^^^^^^^^^^^^^^^^^^
  File "C:\Users\malek\AppData\Local\Programs\Python\Python311\Lib\site-packages\httpx\_client.py", line 1682, in _send_handling_redirects
    response = await self._send_single_request(request)
               ^^^^^^^^^^^^^^^^^^^^^^^^^^^^^^^^^^^^^^^^
  File "C:\Users\malek\AppData\Local\Programs\Python\Python311\Lib\site-packages\httpx\_client.py", line 1719, in _send_single_request
    response = await transport.handle_async_request(request)
               ^^^^^^^^^^^^^^^^^^^^^^^^^^^^^^^^^^^^^^^^^^^^^
  File "C:\Users\malek\AppData\Local\Programs\Python\Python311\Lib\site-packages\httpx\_transports\default.py", line 352, in handle_async_request
    with map_httpcore_exceptions():
  File "C:\Users\malek\AppData\Local\Programs\Python\Python311\Lib\contextlib.py", line 155, in __exit__
    self.gen.throw(typ, value, traceback)
  File "C:\Users\malek\AppData\Local\Programs\Python\Python311\Lib\site-packages\httpx\_transports\default.py", line 77, in map_httpcore_exceptions
    raise mapped_exc(message) from exc
httpx.ConnectError: [Errno 11001] getaddrinfo failed

The above exception was the direct cause of the following exception:

Traceback (most recent call last):
  File "C:\Users\malek\AppData\Local\Programs\Python\Python311\Lib\site-packages\telegram\ext\_updater.py", line 607, in _network_loop_retry
    if not await action_cb():
           ^^^^^^^^^^^^^^^^^
  File "C:\Users\malek\AppData\Local\Programs\Python\Python311\Lib\site-packages\telegram\ext\_updater.py", line 335, in polling_action_cb
    raise exc
  File "C:\Users\malek\AppData\Local\Programs\Python\Python311\Lib\site-packages\telegram\ext\_updater.py", line 320, in polling_action_cb
    updates = await self.bot.get_updates(
              ^^^^^^^^^^^^^^^^^^^^^^^^^^^
  File "C:\Users\malek\AppData\Local\Programs\Python\Python311\Lib\site-packages\telegram\ext\_extbot.py", line 543, in get_updates
    updates = await super().get_updates(
              ^^^^^^^^^^^^^^^^^^^^^^^^^^
  File "C:\Users\malek\AppData\Local\Programs\Python\Python311\Lib\site-packages\telegram\_bot.py", line 381, in decorator
    result = await func(self, *args, **kwargs)  # skipcq: PYL-E1102
             ^^^^^^^^^^^^^^^^^^^^^^^^^^^^^^^^^
  File "C:\Users\malek\AppData\Local\Programs\Python\Python311\Lib\site-packages\telegram\_bot.py", line 3661, in get_updates
    await self._post(
  File "C:\Users\malek\AppData\Local\Programs\Python\Python311\Lib\site-packages\telegram\_bot.py", line 469, in _post
    return await self._do_post(
           ^^^^^^^^^^^^^^^^^^^^
  File "C:\Users\malek\AppData\Local\Programs\Python\Python311\Lib\site-packages\telegram\ext\_extbot.py", line 325, in _do_post
    return await super()._do_post(
           ^^^^^^^^^^^^^^^^^^^^^^^
  File "C:\Users\malek\AppData\Local\Programs\Python\Python311\Lib\site-packages\telegram\_bot.py", line 497, in _do_post
    return await request.post(
           ^^^^^^^^^^^^^^^^^^^
  File "C:\Users\malek\AppData\Local\Programs\Python\Python311\Lib\site-packages\telegram\request\_baserequest.py", line 168, in post
    result = await self._request_wrapper(
             ^^^^^^^^^^^^^^^^^^^^^^^^^^^^
  File "C:\Users\malek\AppData\Local\Programs\Python\Python311\Lib\site-packages\telegram\request\_baserequest.py", line 291, in _request_wrapper
    raise exc
  File "C:\Users\malek\AppData\Local\Programs\Python\Python311\Lib\site-packages\telegram\request\_baserequest.py", line 277, in _request_wrapper
    code, payload = await self.do_request(
                    ^^^^^^^^^^^^^^^^^^^^^^
  File "C:\Users\malek\AppData\Local\Programs\Python\Python311\Lib\site-packages\telegram\request\_httpxrequest.py", line 240, in do_request
    raise NetworkError(f"httpx.{err.__class__.__name__}: {err}") from err
telegram.error.NetworkError: httpx.ConnectError: [Errno 11001] getaddrinfo failed
2025-09-17 14:02:10,279 - telegram.ext.Updater - ERROR - Error while getting Updates: httpx.ConnectError: [Errno 11001] getaddrinfo failed
2025-09-17 14:02:10,280 - telegram.ext.Application - ERROR - No error handlers are registered, logging exception.
Traceback (most recent call last):
  File "C:\Users\malek\AppData\Local\Programs\Python\Python311\Lib\site-packages\httpcore\_exceptions.py", line 10, in map_exceptions
    yield
  File "C:\Users\malek\AppData\Local\Programs\Python\Python311\Lib\site-packages\httpcore\_backends\anyio.py", line 114, in connect_tcp
    stream: anyio.abc.ByteStream = await anyio.connect_tcp(
                                   ^^^^^^^^^^^^^^^^^^^^^^^^
  File "C:\Users\malek\AppData\Local\Programs\Python\Python311\Lib\site-packages\anyio\_core\_sockets.py", line 215, in connect_tcp
    gai_res = await getaddrinfo(
              ^^^^^^^^^^^^^^^^^^
  File "C:\Users\malek\AppData\Local\Programs\Python\Python311\Lib\site-packages\anyio\_core\_sockets.py", line 592, in getaddrinfo
    gai_res = await get_async_backend().getaddrinfo(
              ^^^^^^^^^^^^^^^^^^^^^^^^^^^^^^^^^^^^^^
  File "C:\Users\malek\AppData\Local\Programs\Python\Python311\Lib\site-packages\anyio\_backends\_asyncio.py", line 2698, in getaddrinfo
    return await get_running_loop().getaddrinfo(
           ^^^^^^^^^^^^^^^^^^^^^^^^^^^^^^^^^^^^^
  File "C:\Users\malek\AppData\Local\Programs\Python\Python311\Lib\asyncio\base_events.py", line 864, in getaddrinfo
    return await self.run_in_executor(
           ^^^^^^^^^^^^^^^^^^^^^^^^^^^
  File "C:\Users\malek\AppData\Local\Programs\Python\Python311\Lib\concurrent\futures\thread.py", line 58, in run
    result = self.fn(*self.args, **self.kwargs)
             ^^^^^^^^^^^^^^^^^^^^^^^^^^^^^^^^^^
  File "C:\Users\malek\AppData\Local\Programs\Python\Python311\Lib\socket.py", line 961, in getaddrinfo
    for res in _socket.getaddrinfo(host, port, family, type, proto, flags):
               ^^^^^^^^^^^^^^^^^^^^^^^^^^^^^^^^^^^^^^^^^^^^^^^^^^^^^^^^^^^
socket.gaierror: [Errno 11001] getaddrinfo failed

The above exception was the direct cause of the following exception:

Traceback (most recent call last):
  File "C:\Users\malek\AppData\Local\Programs\Python\Python311\Lib\site-packages\httpx\_transports\default.py", line 60, in map_httpcore_exceptions
    yield
  File "C:\Users\malek\AppData\Local\Programs\Python\Python311\Lib\site-packages\httpx\_transports\default.py", line 353, in handle_async_request
    resp = await self._pool.handle_async_request(req)
           ^^^^^^^^^^^^^^^^^^^^^^^^^^^^^^^^^^^^^^^^^^
  File "C:\Users\malek\AppData\Local\Programs\Python\Python311\Lib\site-packages\httpcore\_async\connection_pool.py", line 262, in handle_async_request
    raise exc
  File "C:\Users\malek\AppData\Local\Programs\Python\Python311\Lib\site-packages\httpcore\_async\connection_pool.py", line 245, in handle_async_request
    response = await connection.handle_async_request(request)
               ^^^^^^^^^^^^^^^^^^^^^^^^^^^^^^^^^^^^^^^^^^^^^^
  File "C:\Users\malek\AppData\Local\Programs\Python\Python311\Lib\site-packages\httpcore\_async\connection.py", line 92, in handle_async_request
    raise exc
  File "C:\Users\malek\AppData\Local\Programs\Python\Python311\Lib\site-packages\httpcore\_async\connection.py", line 69, in handle_async_request
    stream = await self._connect(request)
             ^^^^^^^^^^^^^^^^^^^^^^^^^^^^
  File "C:\Users\malek\AppData\Local\Programs\Python\Python311\Lib\site-packages\httpcore\_async\connection.py", line 117, in _connect
    stream = await self._network_backend.connect_tcp(**kwargs)
             ^^^^^^^^^^^^^^^^^^^^^^^^^^^^^^^^^^^^^^^^^^^^^^^^^
  File "C:\Users\malek\AppData\Local\Programs\Python\Python311\Lib\site-packages\httpcore\_backends\auto.py", line 31, in connect_tcp
    return await self._backend.connect_tcp(
           ^^^^^^^^^^^^^^^^^^^^^^^^^^^^^^^^
  File "C:\Users\malek\AppData\Local\Programs\Python\Python311\Lib\site-packages\httpcore\_backends\anyio.py", line 112, in connect_tcp
    with map_exceptions(exc_map):
  File "C:\Users\malek\AppData\Local\Programs\Python\Python311\Lib\contextlib.py", line 155, in __exit__
    self.gen.throw(typ, value, traceback)
  File "C:\Users\malek\AppData\Local\Programs\Python\Python311\Lib\site-packages\httpcore\_exceptions.py", line 14, in map_exceptions
    raise to_exc(exc) from exc
httpcore.ConnectError: [Errno 11001] getaddrinfo failed

The above exception was the direct cause of the following exception:

Traceback (most recent call last):
  File "C:\Users\malek\AppData\Local\Programs\Python\Python311\Lib\site-packages\telegram\request\_httpxrequest.py", line 216, in do_request
    res = await self._client.request(
          ^^^^^^^^^^^^^^^^^^^^^^^^^^^
  File "C:\Users\malek\AppData\Local\Programs\Python\Python311\Lib\site-packages\httpx\_client.py", line 1530, in request
    return await self.send(request, auth=auth, follow_redirects=follow_redirects)
           ^^^^^^^^^^^^^^^^^^^^^^^^^^^^^^^^^^^^^^^^^^^^^^^^^^^^^^^^^^^^^^^^^^^^^^
  File "C:\Users\malek\AppData\Local\Programs\Python\Python311\Lib\site-packages\httpx\_client.py", line 1617, in send
    response = await self._send_handling_auth(
               ^^^^^^^^^^^^^^^^^^^^^^^^^^^^^^^
  File "C:\Users\malek\AppData\Local\Programs\Python\Python311\Lib\site-packages\httpx\_client.py", line 1645, in _send_handling_auth
    response = await self._send_handling_redirects(
               ^^^^^^^^^^^^^^^^^^^^^^^^^^^^^^^^^^^^
  File "C:\Users\malek\AppData\Local\Programs\Python\Python311\Lib\site-packages\httpx\_client.py", line 1682, in _send_handling_redirects
    response = await self._send_single_request(request)
               ^^^^^^^^^^^^^^^^^^^^^^^^^^^^^^^^^^^^^^^^
  File "C:\Users\malek\AppData\Local\Programs\Python\Python311\Lib\site-packages\httpx\_client.py", line 1719, in _send_single_request
    response = await transport.handle_async_request(request)
               ^^^^^^^^^^^^^^^^^^^^^^^^^^^^^^^^^^^^^^^^^^^^^
  File "C:\Users\malek\AppData\Local\Programs\Python\Python311\Lib\site-packages\httpx\_transports\default.py", line 352, in handle_async_request
    with map_httpcore_exceptions():
  File "C:\Users\malek\AppData\Local\Programs\Python\Python311\Lib\contextlib.py", line 155, in __exit__
    self.gen.throw(typ, value, traceback)
  File "C:\Users\malek\AppData\Local\Programs\Python\Python311\Lib\site-packages\httpx\_transports\default.py", line 77, in map_httpcore_exceptions
    raise mapped_exc(message) from exc
httpx.ConnectError: [Errno 11001] getaddrinfo failed

The above exception was the direct cause of the following exception:

Traceback (most recent call last):
  File "C:\Users\malek\AppData\Local\Programs\Python\Python311\Lib\site-packages\telegram\ext\_updater.py", line 607, in _network_loop_retry
    if not await action_cb():
           ^^^^^^^^^^^^^^^^^
  File "C:\Users\malek\AppData\Local\Programs\Python\Python311\Lib\site-packages\telegram\ext\_updater.py", line 335, in polling_action_cb
    raise exc
  File "C:\Users\malek\AppData\Local\Programs\Python\Python311\Lib\site-packages\telegram\ext\_updater.py", line 320, in polling_action_cb
    updates = await self.bot.get_updates(
              ^^^^^^^^^^^^^^^^^^^^^^^^^^^
  File "C:\Users\malek\AppData\Local\Programs\Python\Python311\Lib\site-packages\telegram\ext\_extbot.py", line 543, in get_updates
    updates = await super().get_updates(
              ^^^^^^^^^^^^^^^^^^^^^^^^^^
  File "C:\Users\malek\AppData\Local\Programs\Python\Python311\Lib\site-packages\telegram\_bot.py", line 381, in decorator
    result = await func(self, *args, **kwargs)  # skipcq: PYL-E1102
             ^^^^^^^^^^^^^^^^^^^^^^^^^^^^^^^^^
  File "C:\Users\malek\AppData\Local\Programs\Python\Python311\Lib\site-packages\telegram\_bot.py", line 3661, in get_updates
    await self._post(
  File "C:\Users\malek\AppData\Local\Programs\Python\Python311\Lib\site-packages\telegram\_bot.py", line 469, in _post
    return await self._do_post(
           ^^^^^^^^^^^^^^^^^^^^
  File "C:\Users\malek\AppData\Local\Programs\Python\Python311\Lib\site-packages\telegram\ext\_extbot.py", line 325, in _do_post
    return await super()._do_post(
           ^^^^^^^^^^^^^^^^^^^^^^^
  File "C:\Users\malek\AppData\Local\Programs\Python\Python311\Lib\site-packages\telegram\_bot.py", line 497, in _do_post
    return await request.post(
           ^^^^^^^^^^^^^^^^^^^
  File "C:\Users\malek\AppData\Local\Programs\Python\Python311\Lib\site-packages\telegram\request\_baserequest.py", line 168, in post
    result = await self._request_wrapper(
             ^^^^^^^^^^^^^^^^^^^^^^^^^^^^
  File "C:\Users\malek\AppData\Local\Programs\Python\Python311\Lib\site-packages\telegram\request\_baserequest.py", line 291, in _request_wrapper
    raise exc
  File "C:\Users\malek\AppData\Local\Programs\Python\Python311\Lib\site-packages\telegram\request\_baserequest.py", line 277, in _request_wrapper
    code, payload = await self.do_request(
                    ^^^^^^^^^^^^^^^^^^^^^^
  File "C:\Users\malek\AppData\Local\Programs\Python\Python311\Lib\site-packages\telegram\request\_httpxrequest.py", line 240, in do_request
    raise NetworkError(f"httpx.{err.__class__.__name__}: {err}") from err
telegram.error.NetworkError: httpx.ConnectError: [Errno 11001] getaddrinfo failed
2025-09-17 14:02:11,789 - telegram.ext.Updater - ERROR - Error while getting Updates: httpx.ConnectError: [Errno 11001] getaddrinfo failed
2025-09-17 14:02:11,793 - telegram.ext.Application - ERROR - No error handlers are registered, logging exception.
Traceback (most recent call last):
  File "C:\Users\malek\AppData\Local\Programs\Python\Python311\Lib\site-packages\httpcore\_exceptions.py", line 10, in map_exceptions
    yield
  File "C:\Users\malek\AppData\Local\Programs\Python\Python311\Lib\site-packages\httpcore\_backends\anyio.py", line 114, in connect_tcp
    stream: anyio.abc.ByteStream = await anyio.connect_tcp(
                                   ^^^^^^^^^^^^^^^^^^^^^^^^
  File "C:\Users\malek\AppData\Local\Programs\Python\Python311\Lib\site-packages\anyio\_core\_sockets.py", line 215, in connect_tcp
    gai_res = await getaddrinfo(
              ^^^^^^^^^^^^^^^^^^
  File "C:\Users\malek\AppData\Local\Programs\Python\Python311\Lib\site-packages\anyio\_core\_sockets.py", line 592, in getaddrinfo
    gai_res = await get_async_backend().getaddrinfo(
              ^^^^^^^^^^^^^^^^^^^^^^^^^^^^^^^^^^^^^^
  File "C:\Users\malek\AppData\Local\Programs\Python\Python311\Lib\site-packages\anyio\_backends\_asyncio.py", line 2698, in getaddrinfo
    return await get_running_loop().getaddrinfo(
           ^^^^^^^^^^^^^^^^^^^^^^^^^^^^^^^^^^^^^
  File "C:\Users\malek\AppData\Local\Programs\Python\Python311\Lib\asyncio\base_events.py", line 864, in getaddrinfo
    return await self.run_in_executor(
           ^^^^^^^^^^^^^^^^^^^^^^^^^^^
  File "C:\Users\malek\AppData\Local\Programs\Python\Python311\Lib\concurrent\futures\thread.py", line 58, in run
    result = self.fn(*self.args, **self.kwargs)
             ^^^^^^^^^^^^^^^^^^^^^^^^^^^^^^^^^^
  File "C:\Users\malek\AppData\Local\Programs\Python\Python311\Lib\socket.py", line 961, in getaddrinfo
    for res in _socket.getaddrinfo(host, port, family, type, proto, flags):
               ^^^^^^^^^^^^^^^^^^^^^^^^^^^^^^^^^^^^^^^^^^^^^^^^^^^^^^^^^^^
socket.gaierror: [Errno 11001] getaddrinfo failed

The above exception was the direct cause of the following exception:

Traceback (most recent call last):
  File "C:\Users\malek\AppData\Local\Programs\Python\Python311\Lib\site-packages\httpx\_transports\default.py", line 60, in map_httpcore_exceptions
    yield
  File "C:\Users\malek\AppData\Local\Programs\Python\Python311\Lib\site-packages\httpx\_transports\default.py", line 353, in handle_async_request
    resp = await self._pool.handle_async_request(req)
           ^^^^^^^^^^^^^^^^^^^^^^^^^^^^^^^^^^^^^^^^^^
  File "C:\Users\malek\AppData\Local\Programs\Python\Python311\Lib\site-packages\httpcore\_async\connection_pool.py", line 262, in handle_async_request
    raise exc
  File "C:\Users\malek\AppData\Local\Programs\Python\Python311\Lib\site-packages\httpcore\_async\connection_pool.py", line 245, in handle_async_request
    response = await connection.handle_async_request(request)
               ^^^^^^^^^^^^^^^^^^^^^^^^^^^^^^^^^^^^^^^^^^^^^^
  File "C:\Users\malek\AppData\Local\Programs\Python\Python311\Lib\site-packages\httpcore\_async\connection.py", line 92, in handle_async_request
    raise exc
  File "C:\Users\malek\AppData\Local\Programs\Python\Python311\Lib\site-packages\httpcore\_async\connection.py", line 69, in handle_async_request
    stream = await self._connect(request)
             ^^^^^^^^^^^^^^^^^^^^^^^^^^^^
  File "C:\Users\malek\AppData\Local\Programs\Python\Python311\Lib\site-packages\httpcore\_async\connection.py", line 117, in _connect
    stream = await self._network_backend.connect_tcp(**kwargs)
             ^^^^^^^^^^^^^^^^^^^^^^^^^^^^^^^^^^^^^^^^^^^^^^^^^
  File "C:\Users\malek\AppData\Local\Programs\Python\Python311\Lib\site-packages\httpcore\_backends\auto.py", line 31, in connect_tcp
    return await self._backend.connect_tcp(
           ^^^^^^^^^^^^^^^^^^^^^^^^^^^^^^^^
  File "C:\Users\malek\AppData\Local\Programs\Python\Python311\Lib\site-packages\httpcore\_backends\anyio.py", line 112, in connect_tcp
    with map_exceptions(exc_map):
  File "C:\Users\malek\AppData\Local\Programs\Python\Python311\Lib\contextlib.py", line 155, in __exit__
    self.gen.throw(typ, value, traceback)
  File "C:\Users\malek\AppData\Local\Programs\Python\Python311\Lib\site-packages\httpcore\_exceptions.py", line 14, in map_exceptions
    raise to_exc(exc) from exc
httpcore.ConnectError: [Errno 11001] getaddrinfo failed

The above exception was the direct cause of the following exception:

Traceback (most recent call last):
  File "C:\Users\malek\AppData\Local\Programs\Python\Python311\Lib\site-packages\telegram\request\_httpxrequest.py", line 216, in do_request
    res = await self._client.request(
          ^^^^^^^^^^^^^^^^^^^^^^^^^^^
  File "C:\Users\malek\AppData\Local\Programs\Python\Python311\Lib\site-packages\httpx\_client.py", line 1530, in request
    return await self.send(request, auth=auth, follow_redirects=follow_redirects)
           ^^^^^^^^^^^^^^^^^^^^^^^^^^^^^^^^^^^^^^^^^^^^^^^^^^^^^^^^^^^^^^^^^^^^^^
  File "C:\Users\malek\AppData\Local\Programs\Python\Python311\Lib\site-packages\httpx\_client.py", line 1617, in send
    response = await self._send_handling_auth(
               ^^^^^^^^^^^^^^^^^^^^^^^^^^^^^^^
  File "C:\Users\malek\AppData\Local\Programs\Python\Python311\Lib\site-packages\httpx\_client.py", line 1645, in _send_handling_auth
    response = await self._send_handling_redirects(
               ^^^^^^^^^^^^^^^^^^^^^^^^^^^^^^^^^^^^
  File "C:\Users\malek\AppData\Local\Programs\Python\Python311\Lib\site-packages\httpx\_client.py", line 1682, in _send_handling_redirects
    response = await self._send_single_request(request)
               ^^^^^^^^^^^^^^^^^^^^^^^^^^^^^^^^^^^^^^^^
  File "C:\Users\malek\AppData\Local\Programs\Python\Python311\Lib\site-packages\httpx\_client.py", line 1719, in _send_single_request
    response = await transport.handle_async_request(request)
               ^^^^^^^^^^^^^^^^^^^^^^^^^^^^^^^^^^^^^^^^^^^^^
  File "C:\Users\malek\AppData\Local\Programs\Python\Python311\Lib\site-packages\httpx\_transports\default.py", line 352, in handle_async_request
    with map_httpcore_exceptions():
  File "C:\Users\malek\AppData\Local\Programs\Python\Python311\Lib\contextlib.py", line 155, in __exit__
    self.gen.throw(typ, value, traceback)
  File "C:\Users\malek\AppData\Local\Programs\Python\Python311\Lib\site-packages\httpx\_transports\default.py", line 77, in map_httpcore_exceptions
    raise mapped_exc(message) from exc
httpx.ConnectError: [Errno 11001] getaddrinfo failed

The above exception was the direct cause of the following exception:

Traceback (most recent call last):
  File "C:\Users\malek\AppData\Local\Programs\Python\Python311\Lib\site-packages\telegram\ext\_updater.py", line 607, in _network_loop_retry
    if not await action_cb():
           ^^^^^^^^^^^^^^^^^
  File "C:\Users\malek\AppData\Local\Programs\Python\Python311\Lib\site-packages\telegram\ext\_updater.py", line 335, in polling_action_cb
    raise exc
  File "C:\Users\malek\AppData\Local\Programs\Python\Python311\Lib\site-packages\telegram\ext\_updater.py", line 320, in polling_action_cb
    updates = await self.bot.get_updates(
              ^^^^^^^^^^^^^^^^^^^^^^^^^^^
  File "C:\Users\malek\AppData\Local\Programs\Python\Python311\Lib\site-packages\telegram\ext\_extbot.py", line 543, in get_updates
    updates = await super().get_updates(
              ^^^^^^^^^^^^^^^^^^^^^^^^^^
  File "C:\Users\malek\AppData\Local\Programs\Python\Python311\Lib\site-packages\telegram\_bot.py", line 381, in decorator
    result = await func(self, *args, **kwargs)  # skipcq: PYL-E1102
             ^^^^^^^^^^^^^^^^^^^^^^^^^^^^^^^^^
  File "C:\Users\malek\AppData\Local\Programs\Python\Python311\Lib\site-packages\telegram\_bot.py", line 3661, in get_updates
    await self._post(
  File "C:\Users\malek\AppData\Local\Programs\Python\Python311\Lib\site-packages\telegram\_bot.py", line 469, in _post
    return await self._do_post(
           ^^^^^^^^^^^^^^^^^^^^
  File "C:\Users\malek\AppData\Local\Programs\Python\Python311\Lib\site-packages\telegram\ext\_extbot.py", line 325, in _do_post
    return await super()._do_post(
           ^^^^^^^^^^^^^^^^^^^^^^^
  File "C:\Users\malek\AppData\Local\Programs\Python\Python311\Lib\site-packages\telegram\_bot.py", line 497, in _do_post
    return await request.post(
           ^^^^^^^^^^^^^^^^^^^
  File "C:\Users\malek\AppData\Local\Programs\Python\Python311\Lib\site-packages\telegram\request\_baserequest.py", line 168, in post
    result = await self._request_wrapper(
             ^^^^^^^^^^^^^^^^^^^^^^^^^^^^
  File "C:\Users\malek\AppData\Local\Programs\Python\Python311\Lib\site-packages\telegram\request\_baserequest.py", line 291, in _request_wrapper
    raise exc
  File "C:\Users\malek\AppData\Local\Programs\Python\Python311\Lib\site-packages\telegram\request\_baserequest.py", line 277, in _request_wrapper
    code, payload = await self.do_request(
                    ^^^^^^^^^^^^^^^^^^^^^^
  File "C:\Users\malek\AppData\Local\Programs\Python\Python311\Lib\site-packages\telegram\request\_httpxrequest.py", line 240, in do_request
    raise NetworkError(f"httpx.{err.__class__.__name__}: {err}") from err
telegram.error.NetworkError: httpx.ConnectError: [Errno 11001] getaddrinfo failed
2025-09-17 14:02:14,072 - telegram.ext.Updater - ERROR - Error while getting Updates: httpx.ConnectError: [Errno 11001] getaddrinfo failed
2025-09-17 14:02:14,072 - telegram.ext.Application - ERROR - No error handlers are registered, logging exception.
Traceback (most recent call last):
  File "C:\Users\malek\AppData\Local\Programs\Python\Python311\Lib\site-packages\httpcore\_exceptions.py", line 10, in map_exceptions
    yield
  File "C:\Users\malek\AppData\Local\Programs\Python\Python311\Lib\site-packages\httpcore\_backends\anyio.py", line 114, in connect_tcp
    stream: anyio.abc.ByteStream = await anyio.connect_tcp(
                                   ^^^^^^^^^^^^^^^^^^^^^^^^
  File "C:\Users\malek\AppData\Local\Programs\Python\Python311\Lib\site-packages\anyio\_core\_sockets.py", line 215, in connect_tcp
    gai_res = await getaddrinfo(
              ^^^^^^^^^^^^^^^^^^
  File "C:\Users\malek\AppData\Local\Programs\Python\Python311\Lib\site-packages\anyio\_core\_sockets.py", line 592, in getaddrinfo
    gai_res = await get_async_backend().getaddrinfo(
              ^^^^^^^^^^^^^^^^^^^^^^^^^^^^^^^^^^^^^^
  File "C:\Users\malek\AppData\Local\Programs\Python\Python311\Lib\site-packages\anyio\_backends\_asyncio.py", line 2698, in getaddrinfo
    return await get_running_loop().getaddrinfo(
           ^^^^^^^^^^^^^^^^^^^^^^^^^^^^^^^^^^^^^
  File "C:\Users\malek\AppData\Local\Programs\Python\Python311\Lib\asyncio\base_events.py", line 864, in getaddrinfo
    return await self.run_in_executor(
           ^^^^^^^^^^^^^^^^^^^^^^^^^^^
  File "C:\Users\malek\AppData\Local\Programs\Python\Python311\Lib\concurrent\futures\thread.py", line 58, in run
    result = self.fn(*self.args, **self.kwargs)
             ^^^^^^^^^^^^^^^^^^^^^^^^^^^^^^^^^^
  File "C:\Users\malek\AppData\Local\Programs\Python\Python311\Lib\socket.py", line 961, in getaddrinfo
    for res in _socket.getaddrinfo(host, port, family, type, proto, flags):
               ^^^^^^^^^^^^^^^^^^^^^^^^^^^^^^^^^^^^^^^^^^^^^^^^^^^^^^^^^^^
socket.gaierror: [Errno 11001] getaddrinfo failed

The above exception was the direct cause of the following exception:

Traceback (most recent call last):
  File "C:\Users\malek\AppData\Local\Programs\Python\Python311\Lib\site-packages\httpx\_transports\default.py", line 60, in map_httpcore_exceptions
    yield
  File "C:\Users\malek\AppData\Local\Programs\Python\Python311\Lib\site-packages\httpx\_transports\default.py", line 353, in handle_async_request
    resp = await self._pool.handle_async_request(req)
           ^^^^^^^^^^^^^^^^^^^^^^^^^^^^^^^^^^^^^^^^^^
  File "C:\Users\malek\AppData\Local\Programs\Python\Python311\Lib\site-packages\httpcore\_async\connection_pool.py", line 262, in handle_async_request
    raise exc
  File "C:\Users\malek\AppData\Local\Programs\Python\Python311\Lib\site-packages\httpcore\_async\connection_pool.py", line 245, in handle_async_request
    response = await connection.handle_async_request(request)
               ^^^^^^^^^^^^^^^^^^^^^^^^^^^^^^^^^^^^^^^^^^^^^^
  File "C:\Users\malek\AppData\Local\Programs\Python\Python311\Lib\site-packages\httpcore\_async\connection.py", line 92, in handle_async_request
    raise exc
  File "C:\Users\malek\AppData\Local\Programs\Python\Python311\Lib\site-packages\httpcore\_async\connection.py", line 69, in handle_async_request
    stream = await self._connect(request)
             ^^^^^^^^^^^^^^^^^^^^^^^^^^^^
  File "C:\Users\malek\AppData\Local\Programs\Python\Python311\Lib\site-packages\httpcore\_async\connection.py", line 117, in _connect
    stream = await self._network_backend.connect_tcp(**kwargs)
             ^^^^^^^^^^^^^^^^^^^^^^^^^^^^^^^^^^^^^^^^^^^^^^^^^
  File "C:\Users\malek\AppData\Local\Programs\Python\Python311\Lib\site-packages\httpcore\_backends\auto.py", line 31, in connect_tcp
    return await self._backend.connect_tcp(
           ^^^^^^^^^^^^^^^^^^^^^^^^^^^^^^^^
  File "C:\Users\malek\AppData\Local\Programs\Python\Python311\Lib\site-packages\httpcore\_backends\anyio.py", line 112, in connect_tcp
    with map_exceptions(exc_map):
  File "C:\Users\malek\AppData\Local\Programs\Python\Python311\Lib\contextlib.py", line 155, in __exit__
    self.gen.throw(typ, value, traceback)
  File "C:\Users\malek\AppData\Local\Programs\Python\Python311\Lib\site-packages\httpcore\_exceptions.py", line 14, in map_exceptions
    raise to_exc(exc) from exc
httpcore.ConnectError: [Errno 11001] getaddrinfo failed

The above exception was the direct cause of the following exception:

Traceback (most recent call last):
  File "C:\Users\malek\AppData\Local\Programs\Python\Python311\Lib\site-packages\telegram\request\_httpxrequest.py", line 216, in do_request
    res = await self._client.request(
          ^^^^^^^^^^^^^^^^^^^^^^^^^^^
  File "C:\Users\malek\AppData\Local\Programs\Python\Python311\Lib\site-packages\httpx\_client.py", line 1530, in request
    return await self.send(request, auth=auth, follow_redirects=follow_redirects)
           ^^^^^^^^^^^^^^^^^^^^^^^^^^^^^^^^^^^^^^^^^^^^^^^^^^^^^^^^^^^^^^^^^^^^^^
  File "C:\Users\malek\AppData\Local\Programs\Python\Python311\Lib\site-packages\httpx\_client.py", line 1617, in send
    response = await self._send_handling_auth(
               ^^^^^^^^^^^^^^^^^^^^^^^^^^^^^^^
  File "C:\Users\malek\AppData\Local\Programs\Python\Python311\Lib\site-packages\httpx\_client.py", line 1645, in _send_handling_auth
    response = await self._send_handling_redirects(
               ^^^^^^^^^^^^^^^^^^^^^^^^^^^^^^^^^^^^
  File "C:\Users\malek\AppData\Local\Programs\Python\Python311\Lib\site-packages\httpx\_client.py", line 1682, in _send_handling_redirects
    response = await self._send_single_request(request)
               ^^^^^^^^^^^^^^^^^^^^^^^^^^^^^^^^^^^^^^^^
  File "C:\Users\malek\AppData\Local\Programs\Python\Python311\Lib\site-packages\httpx\_client.py", line 1719, in _send_single_request
    response = await transport.handle_async_request(request)
               ^^^^^^^^^^^^^^^^^^^^^^^^^^^^^^^^^^^^^^^^^^^^^
  File "C:\Users\malek\AppData\Local\Programs\Python\Python311\Lib\site-packages\httpx\_transports\default.py", line 352, in handle_async_request
    with map_httpcore_exceptions():
  File "C:\Users\malek\AppData\Local\Programs\Python\Python311\Lib\contextlib.py", line 155, in __exit__
    self.gen.throw(typ, value, traceback)
  File "C:\Users\malek\AppData\Local\Programs\Python\Python311\Lib\site-packages\httpx\_transports\default.py", line 77, in map_httpcore_exceptions
    raise mapped_exc(message) from exc
httpx.ConnectError: [Errno 11001] getaddrinfo failed

The above exception was the direct cause of the following exception:

Traceback (most recent call last):
  File "C:\Users\malek\AppData\Local\Programs\Python\Python311\Lib\site-packages\telegram\ext\_updater.py", line 607, in _network_loop_retry
    if not await action_cb():
           ^^^^^^^^^^^^^^^^^
  File "C:\Users\malek\AppData\Local\Programs\Python\Python311\Lib\site-packages\telegram\ext\_updater.py", line 335, in polling_action_cb
    raise exc
  File "C:\Users\malek\AppData\Local\Programs\Python\Python311\Lib\site-packages\telegram\ext\_updater.py", line 320, in polling_action_cb
    updates = await self.bot.get_updates(
              ^^^^^^^^^^^^^^^^^^^^^^^^^^^
  File "C:\Users\malek\AppData\Local\Programs\Python\Python311\Lib\site-packages\telegram\ext\_extbot.py", line 543, in get_updates
    updates = await super().get_updates(
              ^^^^^^^^^^^^^^^^^^^^^^^^^^
  File "C:\Users\malek\AppData\Local\Programs\Python\Python311\Lib\site-packages\telegram\_bot.py", line 381, in decorator
    result = await func(self, *args, **kwargs)  # skipcq: PYL-E1102
             ^^^^^^^^^^^^^^^^^^^^^^^^^^^^^^^^^
  File "C:\Users\malek\AppData\Local\Programs\Python\Python311\Lib\site-packages\telegram\_bot.py", line 3661, in get_updates
    await self._post(
  File "C:\Users\malek\AppData\Local\Programs\Python\Python311\Lib\site-packages\telegram\_bot.py", line 469, in _post
    return await self._do_post(
           ^^^^^^^^^^^^^^^^^^^^
  File "C:\Users\malek\AppData\Local\Programs\Python\Python311\Lib\site-packages\telegram\ext\_extbot.py", line 325, in _do_post
    return await super()._do_post(
           ^^^^^^^^^^^^^^^^^^^^^^^
  File "C:\Users\malek\AppData\Local\Programs\Python\Python311\Lib\site-packages\telegram\_bot.py", line 497, in _do_post
    return await request.post(
           ^^^^^^^^^^^^^^^^^^^
  File "C:\Users\malek\AppData\Local\Programs\Python\Python311\Lib\site-packages\telegram\request\_baserequest.py", line 168, in post
    result = await self._request_wrapper(
             ^^^^^^^^^^^^^^^^^^^^^^^^^^^^
  File "C:\Users\malek\AppData\Local\Programs\Python\Python311\Lib\site-packages\telegram\request\_baserequest.py", line 291, in _request_wrapper
    raise exc
  File "C:\Users\malek\AppData\Local\Programs\Python\Python311\Lib\site-packages\telegram\request\_baserequest.py", line 277, in _request_wrapper
    code, payload = await self.do_request(
                    ^^^^^^^^^^^^^^^^^^^^^^
  File "C:\Users\malek\AppData\Local\Programs\Python\Python311\Lib\site-packages\telegram\request\_httpxrequest.py", line 240, in do_request
    raise NetworkError(f"httpx.{err.__class__.__name__}: {err}") from err
telegram.error.NetworkError: httpx.ConnectError: [Errno 11001] getaddrinfo failed
2025-09-17 14:02:17,461 - telegram.ext.Updater - ERROR - Error while getting Updates: httpx.ConnectError: [Errno 11001] getaddrinfo failed
2025-09-17 14:02:17,461 - telegram.ext.Application - ERROR - No error handlers are registered, logging exception.
Traceback (most recent call last):
  File "C:\Users\malek\AppData\Local\Programs\Python\Python311\Lib\site-packages\httpcore\_exceptions.py", line 10, in map_exceptions
    yield
  File "C:\Users\malek\AppData\Local\Programs\Python\Python311\Lib\site-packages\httpcore\_backends\anyio.py", line 114, in connect_tcp
    stream: anyio.abc.ByteStream = await anyio.connect_tcp(
                                   ^^^^^^^^^^^^^^^^^^^^^^^^
  File "C:\Users\malek\AppData\Local\Programs\Python\Python311\Lib\site-packages\anyio\_core\_sockets.py", line 215, in connect_tcp
    gai_res = await getaddrinfo(
              ^^^^^^^^^^^^^^^^^^
  File "C:\Users\malek\AppData\Local\Programs\Python\Python311\Lib\site-packages\anyio\_core\_sockets.py", line 592, in getaddrinfo
    gai_res = await get_async_backend().getaddrinfo(
              ^^^^^^^^^^^^^^^^^^^^^^^^^^^^^^^^^^^^^^
  File "C:\Users\malek\AppData\Local\Programs\Python\Python311\Lib\site-packages\anyio\_backends\_asyncio.py", line 2698, in getaddrinfo
    return await get_running_loop().getaddrinfo(
           ^^^^^^^^^^^^^^^^^^^^^^^^^^^^^^^^^^^^^
  File "C:\Users\malek\AppData\Local\Programs\Python\Python311\Lib\asyncio\base_events.py", line 864, in getaddrinfo
    return await self.run_in_executor(
           ^^^^^^^^^^^^^^^^^^^^^^^^^^^
  File "C:\Users\malek\AppData\Local\Programs\Python\Python311\Lib\concurrent\futures\thread.py", line 58, in run
    result = self.fn(*self.args, **self.kwargs)
             ^^^^^^^^^^^^^^^^^^^^^^^^^^^^^^^^^^
  File "C:\Users\malek\AppData\Local\Programs\Python\Python311\Lib\socket.py", line 961, in getaddrinfo
    for res in _socket.getaddrinfo(host, port, family, type, proto, flags):
               ^^^^^^^^^^^^^^^^^^^^^^^^^^^^^^^^^^^^^^^^^^^^^^^^^^^^^^^^^^^
socket.gaierror: [Errno 11001] getaddrinfo failed

The above exception was the direct cause of the following exception:

Traceback (most recent call last):
  File "C:\Users\malek\AppData\Local\Programs\Python\Python311\Lib\site-packages\httpx\_transports\default.py", line 60, in map_httpcore_exceptions
    yield
  File "C:\Users\malek\AppData\Local\Programs\Python\Python311\Lib\site-packages\httpx\_transports\default.py", line 353, in handle_async_request
    resp = await self._pool.handle_async_request(req)
           ^^^^^^^^^^^^^^^^^^^^^^^^^^^^^^^^^^^^^^^^^^
  File "C:\Users\malek\AppData\Local\Programs\Python\Python311\Lib\site-packages\httpcore\_async\connection_pool.py", line 262, in handle_async_request
    raise exc
  File "C:\Users\malek\AppData\Local\Programs\Python\Python311\Lib\site-packages\httpcore\_async\connection_pool.py", line 245, in handle_async_request
    response = await connection.handle_async_request(request)
               ^^^^^^^^^^^^^^^^^^^^^^^^^^^^^^^^^^^^^^^^^^^^^^
  File "C:\Users\malek\AppData\Local\Programs\Python\Python311\Lib\site-packages\httpcore\_async\connection.py", line 92, in handle_async_request
    raise exc
  File "C:\Users\malek\AppData\Local\Programs\Python\Python311\Lib\site-packages\httpcore\_async\connection.py", line 69, in handle_async_request
    stream = await self._connect(request)
             ^^^^^^^^^^^^^^^^^^^^^^^^^^^^
  File "C:\Users\malek\AppData\Local\Programs\Python\Python311\Lib\site-packages\httpcore\_async\connection.py", line 117, in _connect
    stream = await self._network_backend.connect_tcp(**kwargs)
             ^^^^^^^^^^^^^^^^^^^^^^^^^^^^^^^^^^^^^^^^^^^^^^^^^
  File "C:\Users\malek\AppData\Local\Programs\Python\Python311\Lib\site-packages\httpcore\_backends\auto.py", line 31, in connect_tcp
    return await self._backend.connect_tcp(
           ^^^^^^^^^^^^^^^^^^^^^^^^^^^^^^^^
  File "C:\Users\malek\AppData\Local\Programs\Python\Python311\Lib\site-packages\httpcore\_backends\anyio.py", line 112, in connect_tcp
    with map_exceptions(exc_map):
  File "C:\Users\malek\AppData\Local\Programs\Python\Python311\Lib\contextlib.py", line 155, in __exit__
    self.gen.throw(typ, value, traceback)
  File "C:\Users\malek\AppData\Local\Programs\Python\Python311\Lib\site-packages\httpcore\_exceptions.py", line 14, in map_exceptions
    raise to_exc(exc) from exc
httpcore.ConnectError: [Errno 11001] getaddrinfo failed

The above exception was the direct cause of the following exception:

Traceback (most recent call last):
  File "C:\Users\malek\AppData\Local\Programs\Python\Python311\Lib\site-packages\telegram\request\_httpxrequest.py", line 216, in do_request
    res = await self._client.request(
          ^^^^^^^^^^^^^^^^^^^^^^^^^^^
  File "C:\Users\malek\AppData\Local\Programs\Python\Python311\Lib\site-packages\httpx\_client.py", line 1530, in request
    return await self.send(request, auth=auth, follow_redirects=follow_redirects)
           ^^^^^^^^^^^^^^^^^^^^^^^^^^^^^^^^^^^^^^^^^^^^^^^^^^^^^^^^^^^^^^^^^^^^^^
  File "C:\Users\malek\AppData\Local\Programs\Python\Python311\Lib\site-packages\httpx\_client.py", line 1617, in send
    response = await self._send_handling_auth(
               ^^^^^^^^^^^^^^^^^^^^^^^^^^^^^^^
  File "C:\Users\malek\AppData\Local\Programs\Python\Python311\Lib\site-packages\httpx\_client.py", line 1645, in _send_handling_auth
    response = await self._send_handling_redirects(
               ^^^^^^^^^^^^^^^^^^^^^^^^^^^^^^^^^^^^
  File "C:\Users\malek\AppData\Local\Programs\Python\Python311\Lib\site-packages\httpx\_client.py", line 1682, in _send_handling_redirects
    response = await self._send_single_request(request)
               ^^^^^^^^^^^^^^^^^^^^^^^^^^^^^^^^^^^^^^^^
  File "C:\Users\malek\AppData\Local\Programs\Python\Python311\Lib\site-packages\httpx\_client.py", line 1719, in _send_single_request
    response = await transport.handle_async_request(request)
               ^^^^^^^^^^^^^^^^^^^^^^^^^^^^^^^^^^^^^^^^^^^^^
  File "C:\Users\malek\AppData\Local\Programs\Python\Python311\Lib\site-packages\httpx\_transports\default.py", line 352, in handle_async_request
    with map_httpcore_exceptions():
  File "C:\Users\malek\AppData\Local\Programs\Python\Python311\Lib\contextlib.py", line 155, in __exit__
    self.gen.throw(typ, value, traceback)
  File "C:\Users\malek\AppData\Local\Programs\Python\Python311\Lib\site-packages\httpx\_transports\default.py", line 77, in map_httpcore_exceptions
    raise mapped_exc(message) from exc
httpx.ConnectError: [Errno 11001] getaddrinfo failed

The above exception was the direct cause of the following exception:

Traceback (most recent call last):
  File "C:\Users\malek\AppData\Local\Programs\Python\Python311\Lib\site-packages\telegram\ext\_updater.py", line 607, in _network_loop_retry
    if not await action_cb():
           ^^^^^^^^^^^^^^^^^
  File "C:\Users\malek\AppData\Local\Programs\Python\Python311\Lib\site-packages\telegram\ext\_updater.py", line 335, in polling_action_cb
    raise exc
  File "C:\Users\malek\AppData\Local\Programs\Python\Python311\Lib\site-packages\telegram\ext\_updater.py", line 320, in polling_action_cb
    updates = await self.bot.get_updates(
              ^^^^^^^^^^^^^^^^^^^^^^^^^^^
  File "C:\Users\malek\AppData\Local\Programs\Python\Python311\Lib\site-packages\telegram\ext\_extbot.py", line 543, in get_updates
    updates = await super().get_updates(
              ^^^^^^^^^^^^^^^^^^^^^^^^^^
  File "C:\Users\malek\AppData\Local\Programs\Python\Python311\Lib\site-packages\telegram\_bot.py", line 381, in decorator
    result = await func(self, *args, **kwargs)  # skipcq: PYL-E1102
             ^^^^^^^^^^^^^^^^^^^^^^^^^^^^^^^^^
  File "C:\Users\malek\AppData\Local\Programs\Python\Python311\Lib\site-packages\telegram\_bot.py", line 3661, in get_updates
    await self._post(
  File "C:\Users\malek\AppData\Local\Programs\Python\Python311\Lib\site-packages\telegram\_bot.py", line 469, in _post
    return await self._do_post(
           ^^^^^^^^^^^^^^^^^^^^
  File "C:\Users\malek\AppData\Local\Programs\Python\Python311\Lib\site-packages\telegram\ext\_extbot.py", line 325, in _do_post
    return await super()._do_post(
           ^^^^^^^^^^^^^^^^^^^^^^^
  File "C:\Users\malek\AppData\Local\Programs\Python\Python311\Lib\site-packages\telegram\_bot.py", line 497, in _do_post
    return await request.post(
           ^^^^^^^^^^^^^^^^^^^
  File "C:\Users\malek\AppData\Local\Programs\Python\Python311\Lib\site-packages\telegram\request\_baserequest.py", line 168, in post
    result = await self._request_wrapper(
             ^^^^^^^^^^^^^^^^^^^^^^^^^^^^
  File "C:\Users\malek\AppData\Local\Programs\Python\Python311\Lib\site-packages\telegram\request\_baserequest.py", line 291, in _request_wrapper
    raise exc
  File "C:\Users\malek\AppData\Local\Programs\Python\Python311\Lib\site-packages\telegram\request\_baserequest.py", line 277, in _request_wrapper
    code, payload = await self.do_request(
                    ^^^^^^^^^^^^^^^^^^^^^^
  File "C:\Users\malek\AppData\Local\Programs\Python\Python311\Lib\site-packages\telegram\request\_httpxrequest.py", line 240, in do_request
    raise NetworkError(f"httpx.{err.__class__.__name__}: {err}") from err
telegram.error.NetworkError: httpx.ConnectError: [Errno 11001] getaddrinfo failed
2025-09-17 14:02:22,544 - telegram.ext.Updater - ERROR - Error while getting Updates: httpx.ConnectError: [Errno 11001] getaddrinfo failed
2025-09-17 14:02:22,544 - telegram.ext.Application - ERROR - No error handlers are registered, logging exception.
Traceback (most recent call last):
  File "C:\Users\malek\AppData\Local\Programs\Python\Python311\Lib\site-packages\httpcore\_exceptions.py", line 10, in map_exceptions
    yield
  File "C:\Users\malek\AppData\Local\Programs\Python\Python311\Lib\site-packages\httpcore\_backends\anyio.py", line 114, in connect_tcp
    stream: anyio.abc.ByteStream = await anyio.connect_tcp(
                                   ^^^^^^^^^^^^^^^^^^^^^^^^
  File "C:\Users\malek\AppData\Local\Programs\Python\Python311\Lib\site-packages\anyio\_core\_sockets.py", line 215, in connect_tcp
    gai_res = await getaddrinfo(
              ^^^^^^^^^^^^^^^^^^
  File "C:\Users\malek\AppData\Local\Programs\Python\Python311\Lib\site-packages\anyio\_core\_sockets.py", line 592, in getaddrinfo
    gai_res = await get_async_backend().getaddrinfo(
              ^^^^^^^^^^^^^^^^^^^^^^^^^^^^^^^^^^^^^^
  File "C:\Users\malek\AppData\Local\Programs\Python\Python311\Lib\site-packages\anyio\_backends\_asyncio.py", line 2698, in getaddrinfo
    return await get_running_loop().getaddrinfo(
           ^^^^^^^^^^^^^^^^^^^^^^^^^^^^^^^^^^^^^
  File "C:\Users\malek\AppData\Local\Programs\Python\Python311\Lib\asyncio\base_events.py", line 864, in getaddrinfo
    return await self.run_in_executor(
           ^^^^^^^^^^^^^^^^^^^^^^^^^^^
  File "C:\Users\malek\AppData\Local\Programs\Python\Python311\Lib\concurrent\futures\thread.py", line 58, in run
    result = self.fn(*self.args, **self.kwargs)
             ^^^^^^^^^^^^^^^^^^^^^^^^^^^^^^^^^^
  File "C:\Users\malek\AppData\Local\Programs\Python\Python311\Lib\socket.py", line 961, in getaddrinfo
    for res in _socket.getaddrinfo(host, port, family, type, proto, flags):
               ^^^^^^^^^^^^^^^^^^^^^^^^^^^^^^^^^^^^^^^^^^^^^^^^^^^^^^^^^^^
socket.gaierror: [Errno 11001] getaddrinfo failed

The above exception was the direct cause of the following exception:

Traceback (most recent call last):
  File "C:\Users\malek\AppData\Local\Programs\Python\Python311\Lib\site-packages\httpx\_transports\default.py", line 60, in map_httpcore_exceptions
    yield
  File "C:\Users\malek\AppData\Local\Programs\Python\Python311\Lib\site-packages\httpx\_transports\default.py", line 353, in handle_async_request
    resp = await self._pool.handle_async_request(req)
           ^^^^^^^^^^^^^^^^^^^^^^^^^^^^^^^^^^^^^^^^^^
  File "C:\Users\malek\AppData\Local\Programs\Python\Python311\Lib\site-packages\httpcore\_async\connection_pool.py", line 262, in handle_async_request
    raise exc
  File "C:\Users\malek\AppData\Local\Programs\Python\Python311\Lib\site-packages\httpcore\_async\connection_pool.py", line 245, in handle_async_request
    response = await connection.handle_async_request(request)
               ^^^^^^^^^^^^^^^^^^^^^^^^^^^^^^^^^^^^^^^^^^^^^^
  File "C:\Users\malek\AppData\Local\Programs\Python\Python311\Lib\site-packages\httpcore\_async\connection.py", line 92, in handle_async_request
    raise exc
  File "C:\Users\malek\AppData\Local\Programs\Python\Python311\Lib\site-packages\httpcore\_async\connection.py", line 69, in handle_async_request
    stream = await self._connect(request)
             ^^^^^^^^^^^^^^^^^^^^^^^^^^^^
  File "C:\Users\malek\AppData\Local\Programs\Python\Python311\Lib\site-packages\httpcore\_async\connection.py", line 117, in _connect
    stream = await self._network_backend.connect_tcp(**kwargs)
             ^^^^^^^^^^^^^^^^^^^^^^^^^^^^^^^^^^^^^^^^^^^^^^^^^
  File "C:\Users\malek\AppData\Local\Programs\Python\Python311\Lib\site-packages\httpcore\_backends\auto.py", line 31, in connect_tcp
    return await self._backend.connect_tcp(
           ^^^^^^^^^^^^^^^^^^^^^^^^^^^^^^^^
  File "C:\Users\malek\AppData\Local\Programs\Python\Python311\Lib\site-packages\httpcore\_backends\anyio.py", line 112, in connect_tcp
    with map_exceptions(exc_map):
  File "C:\Users\malek\AppData\Local\Programs\Python\Python311\Lib\contextlib.py", line 155, in __exit__
    self.gen.throw(typ, value, traceback)
  File "C:\Users\malek\AppData\Local\Programs\Python\Python311\Lib\site-packages\httpcore\_exceptions.py", line 14, in map_exceptions
    raise to_exc(exc) from exc
httpcore.ConnectError: [Errno 11001] getaddrinfo failed

The above exception was the direct cause of the following exception:

Traceback (most recent call last):
  File "C:\Users\malek\AppData\Local\Programs\Python\Python311\Lib\site-packages\telegram\request\_httpxrequest.py", line 216, in do_request
    res = await self._client.request(
          ^^^^^^^^^^^^^^^^^^^^^^^^^^^
  File "C:\Users\malek\AppData\Local\Programs\Python\Python311\Lib\site-packages\httpx\_client.py", line 1530, in request
    return await self.send(request, auth=auth, follow_redirects=follow_redirects)
           ^^^^^^^^^^^^^^^^^^^^^^^^^^^^^^^^^^^^^^^^^^^^^^^^^^^^^^^^^^^^^^^^^^^^^^
  File "C:\Users\malek\AppData\Local\Programs\Python\Python311\Lib\site-packages\httpx\_client.py", line 1617, in send
    response = await self._send_handling_auth(
               ^^^^^^^^^^^^^^^^^^^^^^^^^^^^^^^
  File "C:\Users\malek\AppData\Local\Programs\Python\Python311\Lib\site-packages\httpx\_client.py", line 1645, in _send_handling_auth
    response = await self._send_handling_redirects(
               ^^^^^^^^^^^^^^^^^^^^^^^^^^^^^^^^^^^^
  File "C:\Users\malek\AppData\Local\Programs\Python\Python311\Lib\site-packages\httpx\_client.py", line 1682, in _send_handling_redirects
    response = await self._send_single_request(request)
               ^^^^^^^^^^^^^^^^^^^^^^^^^^^^^^^^^^^^^^^^
  File "C:\Users\malek\AppData\Local\Programs\Python\Python311\Lib\site-packages\httpx\_client.py", line 1719, in _send_single_request
    response = await transport.handle_async_request(request)
               ^^^^^^^^^^^^^^^^^^^^^^^^^^^^^^^^^^^^^^^^^^^^^
  File "C:\Users\malek\AppData\Local\Programs\Python\Python311\Lib\site-packages\httpx\_transports\default.py", line 352, in handle_async_request
    with map_httpcore_exceptions():
  File "C:\Users\malek\AppData\Local\Programs\Python\Python311\Lib\contextlib.py", line 155, in __exit__
    self.gen.throw(typ, value, traceback)
  File "C:\Users\malek\AppData\Local\Programs\Python\Python311\Lib\site-packages\httpx\_transports\default.py", line 77, in map_httpcore_exceptions
    raise mapped_exc(message) from exc
httpx.ConnectError: [Errno 11001] getaddrinfo failed

The above exception was the direct cause of the following exception:

Traceback (most recent call last):
  File "C:\Users\malek\AppData\Local\Programs\Python\Python311\Lib\site-packages\telegram\ext\_updater.py", line 607, in _network_loop_retry
    if not await action_cb():
           ^^^^^^^^^^^^^^^^^
  File "C:\Users\malek\AppData\Local\Programs\Python\Python311\Lib\site-packages\telegram\ext\_updater.py", line 335, in polling_action_cb
    raise exc
  File "C:\Users\malek\AppData\Local\Programs\Python\Python311\Lib\site-packages\telegram\ext\_updater.py", line 320, in polling_action_cb
    updates = await self.bot.get_updates(
              ^^^^^^^^^^^^^^^^^^^^^^^^^^^
  File "C:\Users\malek\AppData\Local\Programs\Python\Python311\Lib\site-packages\telegram\ext\_extbot.py", line 543, in get_updates
    updates = await super().get_updates(
              ^^^^^^^^^^^^^^^^^^^^^^^^^^
  File "C:\Users\malek\AppData\Local\Programs\Python\Python311\Lib\site-packages\telegram\_bot.py", line 381, in decorator
    result = await func(self, *args, **kwargs)  # skipcq: PYL-E1102
             ^^^^^^^^^^^^^^^^^^^^^^^^^^^^^^^^^
  File "C:\Users\malek\AppData\Local\Programs\Python\Python311\Lib\site-packages\telegram\_bot.py", line 3661, in get_updates
    await self._post(
  File "C:\Users\malek\AppData\Local\Programs\Python\Python311\Lib\site-packages\telegram\_bot.py", line 469, in _post
    return await self._do_post(
           ^^^^^^^^^^^^^^^^^^^^
  File "C:\Users\malek\AppData\Local\Programs\Python\Python311\Lib\site-packages\telegram\ext\_extbot.py", line 325, in _do_post
    return await super()._do_post(
           ^^^^^^^^^^^^^^^^^^^^^^^
  File "C:\Users\malek\AppData\Local\Programs\Python\Python311\Lib\site-packages\telegram\_bot.py", line 497, in _do_post
    return await request.post(
           ^^^^^^^^^^^^^^^^^^^
  File "C:\Users\malek\AppData\Local\Programs\Python\Python311\Lib\site-packages\telegram\request\_baserequest.py", line 168, in post
    result = await self._request_wrapper(
             ^^^^^^^^^^^^^^^^^^^^^^^^^^^^
  File "C:\Users\malek\AppData\Local\Programs\Python\Python311\Lib\site-packages\telegram\request\_baserequest.py", line 291, in _request_wrapper
    raise exc
  File "C:\Users\malek\AppData\Local\Programs\Python\Python311\Lib\site-packages\telegram\request\_baserequest.py", line 277, in _request_wrapper
    code, payload = await self.do_request(
                    ^^^^^^^^^^^^^^^^^^^^^^
  File "C:\Users\malek\AppData\Local\Programs\Python\Python311\Lib\site-packages\telegram\request\_httpxrequest.py", line 240, in do_request
    raise NetworkError(f"httpx.{err.__class__.__name__}: {err}") from err
telegram.error.NetworkError: httpx.ConnectError: [Errno 11001] getaddrinfo failed
2025-09-17 14:02:30,155 - telegram.ext.Updater - ERROR - Error while getting Updates: httpx.ConnectError: [Errno 11001] getaddrinfo failed
2025-09-17 14:02:30,155 - telegram.ext.Application - ERROR - No error handlers are registered, logging exception.
Traceback (most recent call last):
  File "C:\Users\malek\AppData\Local\Programs\Python\Python311\Lib\site-packages\httpcore\_exceptions.py", line 10, in map_exceptions
    yield
  File "C:\Users\malek\AppData\Local\Programs\Python\Python311\Lib\site-packages\httpcore\_backends\anyio.py", line 114, in connect_tcp
    stream: anyio.abc.ByteStream = await anyio.connect_tcp(
                                   ^^^^^^^^^^^^^^^^^^^^^^^^
  File "C:\Users\malek\AppData\Local\Programs\Python\Python311\Lib\site-packages\anyio\_core\_sockets.py", line 215, in connect_tcp
    gai_res = await getaddrinfo(
              ^^^^^^^^^^^^^^^^^^
  File "C:\Users\malek\AppData\Local\Programs\Python\Python311\Lib\site-packages\anyio\_core\_sockets.py", line 592, in getaddrinfo
    gai_res = await get_async_backend().getaddrinfo(
              ^^^^^^^^^^^^^^^^^^^^^^^^^^^^^^^^^^^^^^
  File "C:\Users\malek\AppData\Local\Programs\Python\Python311\Lib\site-packages\anyio\_backends\_asyncio.py", line 2698, in getaddrinfo
    return await get_running_loop().getaddrinfo(
           ^^^^^^^^^^^^^^^^^^^^^^^^^^^^^^^^^^^^^
  File "C:\Users\malek\AppData\Local\Programs\Python\Python311\Lib\asyncio\base_events.py", line 864, in getaddrinfo
    return await self.run_in_executor(
           ^^^^^^^^^^^^^^^^^^^^^^^^^^^
  File "C:\Users\malek\AppData\Local\Programs\Python\Python311\Lib\concurrent\futures\thread.py", line 58, in run
    result = self.fn(*self.args, **self.kwargs)
             ^^^^^^^^^^^^^^^^^^^^^^^^^^^^^^^^^^
  File "C:\Users\malek\AppData\Local\Programs\Python\Python311\Lib\socket.py", line 961, in getaddrinfo
    for res in _socket.getaddrinfo(host, port, family, type, proto, flags):
               ^^^^^^^^^^^^^^^^^^^^^^^^^^^^^^^^^^^^^^^^^^^^^^^^^^^^^^^^^^^
socket.gaierror: [Errno 11001] getaddrinfo failed

The above exception was the direct cause of the following exception:

Traceback (most recent call last):
  File "C:\Users\malek\AppData\Local\Programs\Python\Python311\Lib\site-packages\httpx\_transports\default.py", line 60, in map_httpcore_exceptions
    yield
  File "C:\Users\malek\AppData\Local\Programs\Python\Python311\Lib\site-packages\httpx\_transports\default.py", line 353, in handle_async_request
    resp = await self._pool.handle_async_request(req)
           ^^^^^^^^^^^^^^^^^^^^^^^^^^^^^^^^^^^^^^^^^^
  File "C:\Users\malek\AppData\Local\Programs\Python\Python311\Lib\site-packages\httpcore\_async\connection_pool.py", line 262, in handle_async_request
    raise exc
  File "C:\Users\malek\AppData\Local\Programs\Python\Python311\Lib\site-packages\httpcore\_async\connection_pool.py", line 245, in handle_async_request
    response = await connection.handle_async_request(request)
               ^^^^^^^^^^^^^^^^^^^^^^^^^^^^^^^^^^^^^^^^^^^^^^
  File "C:\Users\malek\AppData\Local\Programs\Python\Python311\Lib\site-packages\httpcore\_async\connection.py", line 92, in handle_async_request
    raise exc
  File "C:\Users\malek\AppData\Local\Programs\Python\Python311\Lib\site-packages\httpcore\_async\connection.py", line 69, in handle_async_request
    stream = await self._connect(request)
             ^^^^^^^^^^^^^^^^^^^^^^^^^^^^
  File "C:\Users\malek\AppData\Local\Programs\Python\Python311\Lib\site-packages\httpcore\_async\connection.py", line 117, in _connect
    stream = await self._network_backend.connect_tcp(**kwargs)
             ^^^^^^^^^^^^^^^^^^^^^^^^^^^^^^^^^^^^^^^^^^^^^^^^^
  File "C:\Users\malek\AppData\Local\Programs\Python\Python311\Lib\site-packages\httpcore\_backends\auto.py", line 31, in connect_tcp
    return await self._backend.connect_tcp(
           ^^^^^^^^^^^^^^^^^^^^^^^^^^^^^^^^
  File "C:\Users\malek\AppData\Local\Programs\Python\Python311\Lib\site-packages\httpcore\_backends\anyio.py", line 112, in connect_tcp
    with map_exceptions(exc_map):
  File "C:\Users\malek\AppData\Local\Programs\Python\Python311\Lib\contextlib.py", line 155, in __exit__
    self.gen.throw(typ, value, traceback)
  File "C:\Users\malek\AppData\Local\Programs\Python\Python311\Lib\site-packages\httpcore\_exceptions.py", line 14, in map_exceptions
    raise to_exc(exc) from exc
httpcore.ConnectError: [Errno 11001] getaddrinfo failed

The above exception was the direct cause of the following exception:

Traceback (most recent call last):
  File "C:\Users\malek\AppData\Local\Programs\Python\Python311\Lib\site-packages\telegram\request\_httpxrequest.py", line 216, in do_request
    res = await self._client.request(
          ^^^^^^^^^^^^^^^^^^^^^^^^^^^
  File "C:\Users\malek\AppData\Local\Programs\Python\Python311\Lib\site-packages\httpx\_client.py", line 1530, in request
    return await self.send(request, auth=auth, follow_redirects=follow_redirects)
           ^^^^^^^^^^^^^^^^^^^^^^^^^^^^^^^^^^^^^^^^^^^^^^^^^^^^^^^^^^^^^^^^^^^^^^
  File "C:\Users\malek\AppData\Local\Programs\Python\Python311\Lib\site-packages\httpx\_client.py", line 1617, in send
    response = await self._send_handling_auth(
               ^^^^^^^^^^^^^^^^^^^^^^^^^^^^^^^
  File "C:\Users\malek\AppData\Local\Programs\Python\Python311\Lib\site-packages\httpx\_client.py", line 1645, in _send_handling_auth
    response = await self._send_handling_redirects(
               ^^^^^^^^^^^^^^^^^^^^^^^^^^^^^^^^^^^^
  File "C:\Users\malek\AppData\Local\Programs\Python\Python311\Lib\site-packages\httpx\_client.py", line 1682, in _send_handling_redirects
    response = await self._send_single_request(request)
               ^^^^^^^^^^^^^^^^^^^^^^^^^^^^^^^^^^^^^^^^
  File "C:\Users\malek\AppData\Local\Programs\Python\Python311\Lib\site-packages\httpx\_client.py", line 1719, in _send_single_request
    response = await transport.handle_async_request(request)
               ^^^^^^^^^^^^^^^^^^^^^^^^^^^^^^^^^^^^^^^^^^^^^
  File "C:\Users\malek\AppData\Local\Programs\Python\Python311\Lib\site-packages\httpx\_transports\default.py", line 352, in handle_async_request
    with map_httpcore_exceptions():
  File "C:\Users\malek\AppData\Local\Programs\Python\Python311\Lib\contextlib.py", line 155, in __exit__
    self.gen.throw(typ, value, traceback)
  File "C:\Users\malek\AppData\Local\Programs\Python\Python311\Lib\site-packages\httpx\_transports\default.py", line 77, in map_httpcore_exceptions
    raise mapped_exc(message) from exc
httpx.ConnectError: [Errno 11001] getaddrinfo failed

The above exception was the direct cause of the following exception:

Traceback (most recent call last):
  File "C:\Users\malek\AppData\Local\Programs\Python\Python311\Lib\site-packages\telegram\ext\_updater.py", line 607, in _network_loop_retry
    if not await action_cb():
           ^^^^^^^^^^^^^^^^^
  File "C:\Users\malek\AppData\Local\Programs\Python\Python311\Lib\site-packages\telegram\ext\_updater.py", line 335, in polling_action_cb
    raise exc
  File "C:\Users\malek\AppData\Local\Programs\Python\Python311\Lib\site-packages\telegram\ext\_updater.py", line 320, in polling_action_cb
    updates = await self.bot.get_updates(
              ^^^^^^^^^^^^^^^^^^^^^^^^^^^
  File "C:\Users\malek\AppData\Local\Programs\Python\Python311\Lib\site-packages\telegram\ext\_extbot.py", line 543, in get_updates
    updates = await super().get_updates(
              ^^^^^^^^^^^^^^^^^^^^^^^^^^
  File "C:\Users\malek\AppData\Local\Programs\Python\Python311\Lib\site-packages\telegram\_bot.py", line 381, in decorator
    result = await func(self, *args, **kwargs)  # skipcq: PYL-E1102
             ^^^^^^^^^^^^^^^^^^^^^^^^^^^^^^^^^
  File "C:\Users\malek\AppData\Local\Programs\Python\Python311\Lib\site-packages\telegram\_bot.py", line 3661, in get_updates
    await self._post(
  File "C:\Users\malek\AppData\Local\Programs\Python\Python311\Lib\site-packages\telegram\_bot.py", line 469, in _post
    return await self._do_post(
           ^^^^^^^^^^^^^^^^^^^^
  File "C:\Users\malek\AppData\Local\Programs\Python\Python311\Lib\site-packages\telegram\ext\_extbot.py", line 325, in _do_post
    return await super()._do_post(
           ^^^^^^^^^^^^^^^^^^^^^^^
  File "C:\Users\malek\AppData\Local\Programs\Python\Python311\Lib\site-packages\telegram\_bot.py", line 497, in _do_post
    return await request.post(
           ^^^^^^^^^^^^^^^^^^^
  File "C:\Users\malek\AppData\Local\Programs\Python\Python311\Lib\site-packages\telegram\request\_baserequest.py", line 168, in post
    result = await self._request_wrapper(
             ^^^^^^^^^^^^^^^^^^^^^^^^^^^^
  File "C:\Users\malek\AppData\Local\Programs\Python\Python311\Lib\site-packages\telegram\request\_baserequest.py", line 291, in _request_wrapper
    raise exc
  File "C:\Users\malek\AppData\Local\Programs\Python\Python311\Lib\site-packages\telegram\request\_baserequest.py", line 277, in _request_wrapper
    code, payload = await self.do_request(
                    ^^^^^^^^^^^^^^^^^^^^^^
  File "C:\Users\malek\AppData\Local\Programs\Python\Python311\Lib\site-packages\telegram\request\_httpxrequest.py", line 240, in do_request
    raise NetworkError(f"httpx.{err.__class__.__name__}: {err}") from err
telegram.error.NetworkError: httpx.ConnectError: [Errno 11001] getaddrinfo failed
2025-09-17 14:02:41,554 - telegram.ext.Updater - ERROR - Error while getting Updates: httpx.ConnectError: [Errno 11001] getaddrinfo failed
2025-09-17 14:02:41,554 - telegram.ext.Application - ERROR - No error handlers are registered, logging exception.
Traceback (most recent call last):
  File "C:\Users\malek\AppData\Local\Programs\Python\Python311\Lib\site-packages\httpcore\_exceptions.py", line 10, in map_exceptions
    yield
  File "C:\Users\malek\AppData\Local\Programs\Python\Python311\Lib\site-packages\httpcore\_backends\anyio.py", line 114, in connect_tcp
    stream: anyio.abc.ByteStream = await anyio.connect_tcp(
                                   ^^^^^^^^^^^^^^^^^^^^^^^^
  File "C:\Users\malek\AppData\Local\Programs\Python\Python311\Lib\site-packages\anyio\_core\_sockets.py", line 215, in connect_tcp
    gai_res = await getaddrinfo(
              ^^^^^^^^^^^^^^^^^^
  File "C:\Users\malek\AppData\Local\Programs\Python\Python311\Lib\site-packages\anyio\_core\_sockets.py", line 592, in getaddrinfo
    gai_res = await get_async_backend().getaddrinfo(
              ^^^^^^^^^^^^^^^^^^^^^^^^^^^^^^^^^^^^^^
  File "C:\Users\malek\AppData\Local\Programs\Python\Python311\Lib\site-packages\anyio\_backends\_asyncio.py", line 2698, in getaddrinfo
    return await get_running_loop().getaddrinfo(
           ^^^^^^^^^^^^^^^^^^^^^^^^^^^^^^^^^^^^^
  File "C:\Users\malek\AppData\Local\Programs\Python\Python311\Lib\asyncio\base_events.py", line 864, in getaddrinfo
    return await self.run_in_executor(
           ^^^^^^^^^^^^^^^^^^^^^^^^^^^
  File "C:\Users\malek\AppData\Local\Programs\Python\Python311\Lib\concurrent\futures\thread.py", line 58, in run
    result = self.fn(*self.args, **self.kwargs)
             ^^^^^^^^^^^^^^^^^^^^^^^^^^^^^^^^^^
  File "C:\Users\malek\AppData\Local\Programs\Python\Python311\Lib\socket.py", line 961, in getaddrinfo
    for res in _socket.getaddrinfo(host, port, family, type, proto, flags):
               ^^^^^^^^^^^^^^^^^^^^^^^^^^^^^^^^^^^^^^^^^^^^^^^^^^^^^^^^^^^
socket.gaierror: [Errno 11001] getaddrinfo failed

The above exception was the direct cause of the following exception:

Traceback (most recent call last):
  File "C:\Users\malek\AppData\Local\Programs\Python\Python311\Lib\site-packages\httpx\_transports\default.py", line 60, in map_httpcore_exceptions
    yield
  File "C:\Users\malek\AppData\Local\Programs\Python\Python311\Lib\site-packages\httpx\_transports\default.py", line 353, in handle_async_request
    resp = await self._pool.handle_async_request(req)
           ^^^^^^^^^^^^^^^^^^^^^^^^^^^^^^^^^^^^^^^^^^
  File "C:\Users\malek\AppData\Local\Programs\Python\Python311\Lib\site-packages\httpcore\_async\connection_pool.py", line 262, in handle_async_request
    raise exc
  File "C:\Users\malek\AppData\Local\Programs\Python\Python311\Lib\site-packages\httpcore\_async\connection_pool.py", line 245, in handle_async_request
    response = await connection.handle_async_request(request)
               ^^^^^^^^^^^^^^^^^^^^^^^^^^^^^^^^^^^^^^^^^^^^^^
  File "C:\Users\malek\AppData\Local\Programs\Python\Python311\Lib\site-packages\httpcore\_async\connection.py", line 92, in handle_async_request
    raise exc
  File "C:\Users\malek\AppData\Local\Programs\Python\Python311\Lib\site-packages\httpcore\_async\connection.py", line 69, in handle_async_request
    stream = await self._connect(request)
             ^^^^^^^^^^^^^^^^^^^^^^^^^^^^
  File "C:\Users\malek\AppData\Local\Programs\Python\Python311\Lib\site-packages\httpcore\_async\connection.py", line 117, in _connect
    stream = await self._network_backend.connect_tcp(**kwargs)
             ^^^^^^^^^^^^^^^^^^^^^^^^^^^^^^^^^^^^^^^^^^^^^^^^^
  File "C:\Users\malek\AppData\Local\Programs\Python\Python311\Lib\site-packages\httpcore\_backends\auto.py", line 31, in connect_tcp
    return await self._backend.connect_tcp(
           ^^^^^^^^^^^^^^^^^^^^^^^^^^^^^^^^
  File "C:\Users\malek\AppData\Local\Programs\Python\Python311\Lib\site-packages\httpcore\_backends\anyio.py", line 112, in connect_tcp
    with map_exceptions(exc_map):
  File "C:\Users\malek\AppData\Local\Programs\Python\Python311\Lib\contextlib.py", line 155, in __exit__
    self.gen.throw(typ, value, traceback)
  File "C:\Users\malek\AppData\Local\Programs\Python\Python311\Lib\site-packages\httpcore\_exceptions.py", line 14, in map_exceptions
    raise to_exc(exc) from exc
httpcore.ConnectError: [Errno 11001] getaddrinfo failed

The above exception was the direct cause of the following exception:

Traceback (most recent call last):
  File "C:\Users\malek\AppData\Local\Programs\Python\Python311\Lib\site-packages\telegram\request\_httpxrequest.py", line 216, in do_request
    res = await self._client.request(
          ^^^^^^^^^^^^^^^^^^^^^^^^^^^
  File "C:\Users\malek\AppData\Local\Programs\Python\Python311\Lib\site-packages\httpx\_client.py", line 1530, in request
    return await self.send(request, auth=auth, follow_redirects=follow_redirects)
           ^^^^^^^^^^^^^^^^^^^^^^^^^^^^^^^^^^^^^^^^^^^^^^^^^^^^^^^^^^^^^^^^^^^^^^
  File "C:\Users\malek\AppData\Local\Programs\Python\Python311\Lib\site-packages\httpx\_client.py", line 1617, in send
    response = await self._send_handling_auth(
               ^^^^^^^^^^^^^^^^^^^^^^^^^^^^^^^
  File "C:\Users\malek\AppData\Local\Programs\Python\Python311\Lib\site-packages\httpx\_client.py", line 1645, in _send_handling_auth
    response = await self._send_handling_redirects(
               ^^^^^^^^^^^^^^^^^^^^^^^^^^^^^^^^^^^^
  File "C:\Users\malek\AppData\Local\Programs\Python\Python311\Lib\site-packages\httpx\_client.py", line 1682, in _send_handling_redirects
    response = await self._send_single_request(request)
               ^^^^^^^^^^^^^^^^^^^^^^^^^^^^^^^^^^^^^^^^
  File "C:\Users\malek\AppData\Local\Programs\Python\Python311\Lib\site-packages\httpx\_client.py", line 1719, in _send_single_request
    response = await transport.handle_async_request(request)
               ^^^^^^^^^^^^^^^^^^^^^^^^^^^^^^^^^^^^^^^^^^^^^
  File "C:\Users\malek\AppData\Local\Programs\Python\Python311\Lib\site-packages\httpx\_transports\default.py", line 352, in handle_async_request
    with map_httpcore_exceptions():
  File "C:\Users\malek\AppData\Local\Programs\Python\Python311\Lib\contextlib.py", line 155, in __exit__
    self.gen.throw(typ, value, traceback)
  File "C:\Users\malek\AppData\Local\Programs\Python\Python311\Lib\site-packages\httpx\_transports\default.py", line 77, in map_httpcore_exceptions
    raise mapped_exc(message) from exc
httpx.ConnectError: [Errno 11001] getaddrinfo failed

The above exception was the direct cause of the following exception:

Traceback (most recent call last):
  File "C:\Users\malek\AppData\Local\Programs\Python\Python311\Lib\site-packages\telegram\ext\_updater.py", line 607, in _network_loop_retry
    if not await action_cb():
           ^^^^^^^^^^^^^^^^^
  File "C:\Users\malek\AppData\Local\Programs\Python\Python311\Lib\site-packages\telegram\ext\_updater.py", line 335, in polling_action_cb
    raise exc
  File "C:\Users\malek\AppData\Local\Programs\Python\Python311\Lib\site-packages\telegram\ext\_updater.py", line 320, in polling_action_cb
    updates = await self.bot.get_updates(
              ^^^^^^^^^^^^^^^^^^^^^^^^^^^
  File "C:\Users\malek\AppData\Local\Programs\Python\Python311\Lib\site-packages\telegram\ext\_extbot.py", line 543, in get_updates
    updates = await super().get_updates(
              ^^^^^^^^^^^^^^^^^^^^^^^^^^
  File "C:\Users\malek\AppData\Local\Programs\Python\Python311\Lib\site-packages\telegram\_bot.py", line 381, in decorator
    result = await func(self, *args, **kwargs)  # skipcq: PYL-E1102
             ^^^^^^^^^^^^^^^^^^^^^^^^^^^^^^^^^
  File "C:\Users\malek\AppData\Local\Programs\Python\Python311\Lib\site-packages\telegram\_bot.py", line 3661, in get_updates
    await self._post(
  File "C:\Users\malek\AppData\Local\Programs\Python\Python311\Lib\site-packages\telegram\_bot.py", line 469, in _post
    return await self._do_post(
           ^^^^^^^^^^^^^^^^^^^^
  File "C:\Users\malek\AppData\Local\Programs\Python\Python311\Lib\site-packages\telegram\ext\_extbot.py", line 325, in _do_post
    return await super()._do_post(
           ^^^^^^^^^^^^^^^^^^^^^^^
  File "C:\Users\malek\AppData\Local\Programs\Python\Python311\Lib\site-packages\telegram\_bot.py", line 497, in _do_post
    return await request.post(
           ^^^^^^^^^^^^^^^^^^^
  File "C:\Users\malek\AppData\Local\Programs\Python\Python311\Lib\site-packages\telegram\request\_baserequest.py", line 168, in post
    result = await self._request_wrapper(
             ^^^^^^^^^^^^^^^^^^^^^^^^^^^^
  File "C:\Users\malek\AppData\Local\Programs\Python\Python311\Lib\site-packages\telegram\request\_baserequest.py", line 291, in _request_wrapper
    raise exc
  File "C:\Users\malek\AppData\Local\Programs\Python\Python311\Lib\site-packages\telegram\request\_baserequest.py", line 277, in _request_wrapper
    code, payload = await self.do_request(
                    ^^^^^^^^^^^^^^^^^^^^^^
  File "C:\Users\malek\AppData\Local\Programs\Python\Python311\Lib\site-packages\telegram\request\_httpxrequest.py", line 240, in do_request
    raise NetworkError(f"httpx.{err.__class__.__name__}: {err}") from err
telegram.error.NetworkError: httpx.ConnectError: [Errno 11001] getaddrinfo failed
2025-09-17 15:13:36,110 - telegram.ext.Updater - ERROR - Error while getting Updates: httpx.ReadError: 
2025-09-17 15:13:36,478 - telegram.ext.Application - ERROR - No error handlers are registered, logging exception.
Traceback (most recent call last):
  File "C:\Users\malek\AppData\Local\Programs\Python\Python311\Lib\site-packages\httpcore\_exceptions.py", line 10, in map_exceptions
    yield
  File "C:\Users\malek\AppData\Local\Programs\Python\Python311\Lib\site-packages\httpcore\_backends\anyio.py", line 34, in read
    return await self._stream.receive(max_bytes=max_bytes)
           ^^^^^^^^^^^^^^^^^^^^^^^^^^^^^^^^^^^^^^^^^^^^^^^
  File "C:\Users\malek\AppData\Local\Programs\Python\Python311\Lib\site-packages\anyio\streams\tls.py", line 237, in receive
    data = await self._call_sslobject_method(self._ssl_object.read, max_bytes)
           ^^^^^^^^^^^^^^^^^^^^^^^^^^^^^^^^^^^^^^^^^^^^^^^^^^^^^^^^^^^^^^^^^^^
  File "C:\Users\malek\AppData\Local\Programs\Python\Python311\Lib\site-packages\anyio\streams\tls.py", line 180, in _call_sslobject_method
    data = await self.transport_stream.receive()
           ^^^^^^^^^^^^^^^^^^^^^^^^^^^^^^^^^^^^^
  File "C:\Users\malek\AppData\Local\Programs\Python\Python311\Lib\site-packages\anyio\_backends\_asyncio.py", line 1265, in receive
    raise self._protocol.exception from None
anyio.BrokenResourceError

The above exception was the direct cause of the following exception:

Traceback (most recent call last):
  File "C:\Users\malek\AppData\Local\Programs\Python\Python311\Lib\site-packages\httpx\_transports\default.py", line 60, in map_httpcore_exceptions
    yield
  File "C:\Users\malek\AppData\Local\Programs\Python\Python311\Lib\site-packages\httpx\_transports\default.py", line 353, in handle_async_request
    resp = await self._pool.handle_async_request(req)
           ^^^^^^^^^^^^^^^^^^^^^^^^^^^^^^^^^^^^^^^^^^
  File "C:\Users\malek\AppData\Local\Programs\Python\Python311\Lib\site-packages\httpcore\_async\connection_pool.py", line 262, in handle_async_request
    raise exc
  File "C:\Users\malek\AppData\Local\Programs\Python\Python311\Lib\site-packages\httpcore\_async\connection_pool.py", line 245, in handle_async_request
    response = await connection.handle_async_request(request)
               ^^^^^^^^^^^^^^^^^^^^^^^^^^^^^^^^^^^^^^^^^^^^^^
  File "C:\Users\malek\AppData\Local\Programs\Python\Python311\Lib\site-packages\httpcore\_async\connection.py", line 96, in handle_async_request
    return await self._connection.handle_async_request(request)
           ^^^^^^^^^^^^^^^^^^^^^^^^^^^^^^^^^^^^^^^^^^^^^^^^^^^^
  File "C:\Users\malek\AppData\Local\Programs\Python\Python311\Lib\site-packages\httpcore\_async\http11.py", line 121, in handle_async_request
    raise exc
  File "C:\Users\malek\AppData\Local\Programs\Python\Python311\Lib\site-packages\httpcore\_async\http11.py", line 99, in handle_async_request
    ) = await self._receive_response_headers(**kwargs)
        ^^^^^^^^^^^^^^^^^^^^^^^^^^^^^^^^^^^^^^^^^^^^^^
  File "C:\Users\malek\AppData\Local\Programs\Python\Python311\Lib\site-packages\httpcore\_async\http11.py", line 164, in _receive_response_headers
    event = await self._receive_event(timeout=timeout)
            ^^^^^^^^^^^^^^^^^^^^^^^^^^^^^^^^^^^^^^^^^^
  File "C:\Users\malek\AppData\Local\Programs\Python\Python311\Lib\site-packages\httpcore\_async\http11.py", line 200, in _receive_event
    data = await self._network_stream.read(
           ^^^^^^^^^^^^^^^^^^^^^^^^^^^^^^^^
  File "C:\Users\malek\AppData\Local\Programs\Python\Python311\Lib\site-packages\httpcore\_backends\anyio.py", line 31, in read
    with map_exceptions(exc_map):
  File "C:\Users\malek\AppData\Local\Programs\Python\Python311\Lib\contextlib.py", line 155, in __exit__
    self.gen.throw(typ, value, traceback)
  File "C:\Users\malek\AppData\Local\Programs\Python\Python311\Lib\site-packages\httpcore\_exceptions.py", line 14, in map_exceptions
    raise to_exc(exc) from exc
httpcore.ReadError

The above exception was the direct cause of the following exception:

Traceback (most recent call last):
  File "C:\Users\malek\AppData\Local\Programs\Python\Python311\Lib\site-packages\telegram\request\_httpxrequest.py", line 216, in do_request
    res = await self._client.request(
          ^^^^^^^^^^^^^^^^^^^^^^^^^^^
  File "C:\Users\malek\AppData\Local\Programs\Python\Python311\Lib\site-packages\httpx\_client.py", line 1530, in request
    return await self.send(request, auth=auth, follow_redirects=follow_redirects)
           ^^^^^^^^^^^^^^^^^^^^^^^^^^^^^^^^^^^^^^^^^^^^^^^^^^^^^^^^^^^^^^^^^^^^^^
  File "C:\Users\malek\AppData\Local\Programs\Python\Python311\Lib\site-packages\httpx\_client.py", line 1617, in send
    response = await self._send_handling_auth(
               ^^^^^^^^^^^^^^^^^^^^^^^^^^^^^^^
  File "C:\Users\malek\AppData\Local\Programs\Python\Python311\Lib\site-packages\httpx\_client.py", line 1645, in _send_handling_auth
    response = await self._send_handling_redirects(
               ^^^^^^^^^^^^^^^^^^^^^^^^^^^^^^^^^^^^
  File "C:\Users\malek\AppData\Local\Programs\Python\Python311\Lib\site-packages\httpx\_client.py", line 1682, in _send_handling_redirects
    response = await self._send_single_request(request)
               ^^^^^^^^^^^^^^^^^^^^^^^^^^^^^^^^^^^^^^^^
  File "C:\Users\malek\AppData\Local\Programs\Python\Python311\Lib\site-packages\httpx\_client.py", line 1719, in _send_single_request
    response = await transport.handle_async_request(request)
               ^^^^^^^^^^^^^^^^^^^^^^^^^^^^^^^^^^^^^^^^^^^^^
  File "C:\Users\malek\AppData\Local\Programs\Python\Python311\Lib\site-packages\httpx\_transports\default.py", line 352, in handle_async_request
    with map_httpcore_exceptions():
  File "C:\Users\malek\AppData\Local\Programs\Python\Python311\Lib\contextlib.py", line 155, in __exit__
    self.gen.throw(typ, value, traceback)
  File "C:\Users\malek\AppData\Local\Programs\Python\Python311\Lib\site-packages\httpx\_transports\default.py", line 77, in map_httpcore_exceptions
    raise mapped_exc(message) from exc
httpx.ReadError

The above exception was the direct cause of the following exception:

Traceback (most recent call last):
  File "C:\Users\malek\AppData\Local\Programs\Python\Python311\Lib\site-packages\telegram\ext\_updater.py", line 607, in _network_loop_retry
    if not await action_cb():
           ^^^^^^^^^^^^^^^^^
  File "C:\Users\malek\AppData\Local\Programs\Python\Python311\Lib\site-packages\telegram\ext\_updater.py", line 335, in polling_action_cb
    raise exc
  File "C:\Users\malek\AppData\Local\Programs\Python\Python311\Lib\site-packages\telegram\ext\_updater.py", line 320, in polling_action_cb
    updates = await self.bot.get_updates(
              ^^^^^^^^^^^^^^^^^^^^^^^^^^^
  File "C:\Users\malek\AppData\Local\Programs\Python\Python311\Lib\site-packages\telegram\ext\_extbot.py", line 543, in get_updates
    updates = await super().get_updates(
              ^^^^^^^^^^^^^^^^^^^^^^^^^^
  File "C:\Users\malek\AppData\Local\Programs\Python\Python311\Lib\site-packages\telegram\_bot.py", line 381, in decorator
    result = await func(self, *args, **kwargs)  # skipcq: PYL-E1102
             ^^^^^^^^^^^^^^^^^^^^^^^^^^^^^^^^^
  File "C:\Users\malek\AppData\Local\Programs\Python\Python311\Lib\site-packages\telegram\_bot.py", line 3661, in get_updates
    await self._post(
  File "C:\Users\malek\AppData\Local\Programs\Python\Python311\Lib\site-packages\telegram\_bot.py", line 469, in _post
    return await self._do_post(
           ^^^^^^^^^^^^^^^^^^^^
  File "C:\Users\malek\AppData\Local\Programs\Python\Python311\Lib\site-packages\telegram\ext\_extbot.py", line 325, in _do_post
    return await super()._do_post(
           ^^^^^^^^^^^^^^^^^^^^^^^
  File "C:\Users\malek\AppData\Local\Programs\Python\Python311\Lib\site-packages\telegram\_bot.py", line 497, in _do_post
    return await request.post(
           ^^^^^^^^^^^^^^^^^^^
  File "C:\Users\malek\AppData\Local\Programs\Python\Python311\Lib\site-packages\telegram\request\_baserequest.py", line 168, in post
    result = await self._request_wrapper(
             ^^^^^^^^^^^^^^^^^^^^^^^^^^^^
  File "C:\Users\malek\AppData\Local\Programs\Python\Python311\Lib\site-packages\telegram\request\_baserequest.py", line 291, in _request_wrapper
    raise exc
  File "C:\Users\malek\AppData\Local\Programs\Python\Python311\Lib\site-packages\telegram\request\_baserequest.py", line 277, in _request_wrapper
    code, payload = await self.do_request(
                    ^^^^^^^^^^^^^^^^^^^^^^
  File "C:\Users\malek\AppData\Local\Programs\Python\Python311\Lib\site-packages\telegram\request\_httpxrequest.py", line 240, in do_request
    raise NetworkError(f"httpx.{err.__class__.__name__}: {err}") from err
telegram.error.NetworkError: httpx.ReadError: 
2025-09-18 15:51:48,950 - telegram.ext.Updater - ERROR - Error while getting Updates: Conflict: terminated by other getUpdates request; make sure that only one bot instance is running
2025-09-18 15:51:48,951 - telegram.ext.Application - ERROR - No error handlers are registered, logging exception.
Traceback (most recent call last):
  File "C:\Users\malek\AppData\Local\Programs\Python\Python311\Lib\site-packages\telegram\ext\_updater.py", line 607, in _network_loop_retry
    if not await action_cb():
           ^^^^^^^^^^^^^^^^^
  File "C:\Users\malek\AppData\Local\Programs\Python\Python311\Lib\site-packages\telegram\ext\_updater.py", line 335, in polling_action_cb
    raise exc
  File "C:\Users\malek\AppData\Local\Programs\Python\Python311\Lib\site-packages\telegram\ext\_updater.py", line 320, in polling_action_cb
    updates = await self.bot.get_updates(
              ^^^^^^^^^^^^^^^^^^^^^^^^^^^
  File "C:\Users\malek\AppData\Local\Programs\Python\Python311\Lib\site-packages\telegram\ext\_extbot.py", line 543, in get_updates
    updates = await super().get_updates(
              ^^^^^^^^^^^^^^^^^^^^^^^^^^
  File "C:\Users\malek\AppData\Local\Programs\Python\Python311\Lib\site-packages\telegram\_bot.py", line 381, in decorator
    result = await func(self, *args, **kwargs)  # skipcq: PYL-E1102
             ^^^^^^^^^^^^^^^^^^^^^^^^^^^^^^^^^
  File "C:\Users\malek\AppData\Local\Programs\Python\Python311\Lib\site-packages\telegram\_bot.py", line 3661, in get_updates
    await self._post(
  File "C:\Users\malek\AppData\Local\Programs\Python\Python311\Lib\site-packages\telegram\_bot.py", line 469, in _post
    return await self._do_post(
           ^^^^^^^^^^^^^^^^^^^^
  File "C:\Users\malek\AppData\Local\Programs\Python\Python311\Lib\site-packages\telegram\ext\_extbot.py", line 325, in _do_post
    return await super()._do_post(
           ^^^^^^^^^^^^^^^^^^^^^^^
  File "C:\Users\malek\AppData\Local\Programs\Python\Python311\Lib\site-packages\telegram\_bot.py", line 497, in _do_post
    return await request.post(
           ^^^^^^^^^^^^^^^^^^^
  File "C:\Users\malek\AppData\Local\Programs\Python\Python311\Lib\site-packages\telegram\request\_baserequest.py", line 168, in post
    result = await self._request_wrapper(
             ^^^^^^^^^^^^^^^^^^^^^^^^^^^^
  File "C:\Users\malek\AppData\Local\Programs\Python\Python311\Lib\site-packages\telegram\request\_baserequest.py", line 330, in _request_wrapper
    raise Conflict(message)
telegram.error.Conflict: Conflict: terminated by other getUpdates request; make sure that only one bot instance is running
2025-09-18 15:51:54,314 - telegram.ext.Updater - ERROR - Error while getting Updates: Conflict: terminated by other getUpdates request; make sure that only one bot instance is running
2025-09-18 15:51:54,314 - telegram.ext.Application - ERROR - No error handlers are registered, logging exception.
Traceback (most recent call last):
  File "C:\Users\malek\AppData\Local\Programs\Python\Python311\Lib\site-packages\telegram\ext\_updater.py", line 607, in _network_loop_retry
    if not await action_cb():
           ^^^^^^^^^^^^^^^^^
  File "C:\Users\malek\AppData\Local\Programs\Python\Python311\Lib\site-packages\telegram\ext\_updater.py", line 335, in polling_action_cb
    raise exc
  File "C:\Users\malek\AppData\Local\Programs\Python\Python311\Lib\site-packages\telegram\ext\_updater.py", line 320, in polling_action_cb
    updates = await self.bot.get_updates(
              ^^^^^^^^^^^^^^^^^^^^^^^^^^^
  File "C:\Users\malek\AppData\Local\Programs\Python\Python311\Lib\site-packages\telegram\ext\_extbot.py", line 543, in get_updates
    updates = await super().get_updates(
              ^^^^^^^^^^^^^^^^^^^^^^^^^^
  File "C:\Users\malek\AppData\Local\Programs\Python\Python311\Lib\site-packages\telegram\_bot.py", line 381, in decorator
    result = await func(self, *args, **kwargs)  # skipcq: PYL-E1102
             ^^^^^^^^^^^^^^^^^^^^^^^^^^^^^^^^^
  File "C:\Users\malek\AppData\Local\Programs\Python\Python311\Lib\site-packages\telegram\_bot.py", line 3661, in get_updates
    await self._post(
  File "C:\Users\malek\AppData\Local\Programs\Python\Python311\Lib\site-packages\telegram\_bot.py", line 469, in _post
    return await self._do_post(
           ^^^^^^^^^^^^^^^^^^^^
  File "C:\Users\malek\AppData\Local\Programs\Python\Python311\Lib\site-packages\telegram\ext\_extbot.py", line 325, in _do_post
    return await super()._do_post(
           ^^^^^^^^^^^^^^^^^^^^^^^
  File "C:\Users\malek\AppData\Local\Programs\Python\Python311\Lib\site-packages\telegram\_bot.py", line 497, in _do_post
    return await request.post(
           ^^^^^^^^^^^^^^^^^^^
  File "C:\Users\malek\AppData\Local\Programs\Python\Python311\Lib\site-packages\telegram\request\_baserequest.py", line 168, in post
    result = await self._request_wrapper(
             ^^^^^^^^^^^^^^^^^^^^^^^^^^^^
  File "C:\Users\malek\AppData\Local\Programs\Python\Python311\Lib\site-packages\telegram\request\_baserequest.py", line 330, in _request_wrapper
    raise Conflict(message)
telegram.error.Conflict: Conflict: terminated by other getUpdates request; make sure that only one bot instance is running
2025-09-18 15:52:05,915 - telegram.ext.Updater - ERROR - Error while getting Updates: Conflict: terminated by other getUpdates request; make sure that only one bot instance is running
2025-09-18 15:52:05,915 - telegram.ext.Application - ERROR - No error handlers are registered, logging exception.
Traceback (most recent call last):
  File "C:\Users\malek\AppData\Local\Programs\Python\Python311\Lib\site-packages\telegram\ext\_updater.py", line 607, in _network_loop_retry
    if not await action_cb():
           ^^^^^^^^^^^^^^^^^
  File "C:\Users\malek\AppData\Local\Programs\Python\Python311\Lib\site-packages\telegram\ext\_updater.py", line 335, in polling_action_cb
    raise exc
  File "C:\Users\malek\AppData\Local\Programs\Python\Python311\Lib\site-packages\telegram\ext\_updater.py", line 320, in polling_action_cb
    updates = await self.bot.get_updates(
              ^^^^^^^^^^^^^^^^^^^^^^^^^^^
  File "C:\Users\malek\AppData\Local\Programs\Python\Python311\Lib\site-packages\telegram\ext\_extbot.py", line 543, in get_updates
    updates = await super().get_updates(
              ^^^^^^^^^^^^^^^^^^^^^^^^^^
  File "C:\Users\malek\AppData\Local\Programs\Python\Python311\Lib\site-packages\telegram\_bot.py", line 381, in decorator
    result = await func(self, *args, **kwargs)  # skipcq: PYL-E1102
             ^^^^^^^^^^^^^^^^^^^^^^^^^^^^^^^^^
  File "C:\Users\malek\AppData\Local\Programs\Python\Python311\Lib\site-packages\telegram\_bot.py", line 3661, in get_updates
    await self._post(
  File "C:\Users\malek\AppData\Local\Programs\Python\Python311\Lib\site-packages\telegram\_bot.py", line 469, in _post
    return await self._do_post(
           ^^^^^^^^^^^^^^^^^^^^
  File "C:\Users\malek\AppData\Local\Programs\Python\Python311\Lib\site-packages\telegram\ext\_extbot.py", line 325, in _do_post
    return await super()._do_post(
           ^^^^^^^^^^^^^^^^^^^^^^^
  File "C:\Users\malek\AppData\Local\Programs\Python\Python311\Lib\site-packages\telegram\_bot.py", line 497, in _do_post
    return await request.post(
           ^^^^^^^^^^^^^^^^^^^
  File "C:\Users\malek\AppData\Local\Programs\Python\Python311\Lib\site-packages\telegram\request\_baserequest.py", line 168, in post
    result = await self._request_wrapper(
             ^^^^^^^^^^^^^^^^^^^^^^^^^^^^
  File "C:\Users\malek\AppData\Local\Programs\Python\Python311\Lib\site-packages\telegram\request\_baserequest.py", line 330, in _request_wrapper
    raise Conflict(message)
telegram.error.Conflict: Conflict: terminated by other getUpdates request; make sure that only one bot instance is running
2025-09-18 15:52:14,164 - telegram.ext.Updater - ERROR - Error while getting Updates: Conflict: terminated by other getUpdates request; make sure that only one bot instance is running
2025-09-18 15:52:14,164 - telegram.ext.Application - ERROR - No error handlers are registered, logging exception.
Traceback (most recent call last):
  File "C:\Users\malek\AppData\Local\Programs\Python\Python311\Lib\site-packages\telegram\ext\_updater.py", line 607, in _network_loop_retry
    if not await action_cb():
           ^^^^^^^^^^^^^^^^^
  File "C:\Users\malek\AppData\Local\Programs\Python\Python311\Lib\site-packages\telegram\ext\_updater.py", line 335, in polling_action_cb
    raise exc
  File "C:\Users\malek\AppData\Local\Programs\Python\Python311\Lib\site-packages\telegram\ext\_updater.py", line 320, in polling_action_cb
    updates = await self.bot.get_updates(
              ^^^^^^^^^^^^^^^^^^^^^^^^^^^
  File "C:\Users\malek\AppData\Local\Programs\Python\Python311\Lib\site-packages\telegram\ext\_extbot.py", line 543, in get_updates
    updates = await super().get_updates(
              ^^^^^^^^^^^^^^^^^^^^^^^^^^
  File "C:\Users\malek\AppData\Local\Programs\Python\Python311\Lib\site-packages\telegram\_bot.py", line 381, in decorator
    result = await func(self, *args, **kwargs)  # skipcq: PYL-E1102
             ^^^^^^^^^^^^^^^^^^^^^^^^^^^^^^^^^
  File "C:\Users\malek\AppData\Local\Programs\Python\Python311\Lib\site-packages\telegram\_bot.py", line 3661, in get_updates
    await self._post(
  File "C:\Users\malek\AppData\Local\Programs\Python\Python311\Lib\site-packages\telegram\_bot.py", line 469, in _post
    return await self._do_post(
           ^^^^^^^^^^^^^^^^^^^^
  File "C:\Users\malek\AppData\Local\Programs\Python\Python311\Lib\site-packages\telegram\ext\_extbot.py", line 325, in _do_post
    return await super()._do_post(
           ^^^^^^^^^^^^^^^^^^^^^^^
  File "C:\Users\malek\AppData\Local\Programs\Python\Python311\Lib\site-packages\telegram\_bot.py", line 497, in _do_post
    return await request.post(
           ^^^^^^^^^^^^^^^^^^^
  File "C:\Users\malek\AppData\Local\Programs\Python\Python311\Lib\site-packages\telegram\request\_baserequest.py", line 168, in post
    result = await self._request_wrapper(
             ^^^^^^^^^^^^^^^^^^^^^^^^^^^^
  File "C:\Users\malek\AppData\Local\Programs\Python\Python311\Lib\site-packages\telegram\request\_baserequest.py", line 330, in _request_wrapper
    raise Conflict(message)
telegram.error.Conflict: Conflict: terminated by other getUpdates request; make sure that only one bot instance is running
2025-09-18 15:52:27,146 - telegram.ext.Updater - ERROR - Error while getting Updates: Conflict: terminated by other getUpdates request; make sure that only one bot instance is running
2025-09-18 15:52:27,147 - telegram.ext.Application - ERROR - No error handlers are registered, logging exception.
Traceback (most recent call last):
  File "C:\Users\malek\AppData\Local\Programs\Python\Python311\Lib\site-packages\telegram\ext\_updater.py", line 607, in _network_loop_retry
    if not await action_cb():
           ^^^^^^^^^^^^^^^^^
  File "C:\Users\malek\AppData\Local\Programs\Python\Python311\Lib\site-packages\telegram\ext\_updater.py", line 335, in polling_action_cb
    raise exc
  File "C:\Users\malek\AppData\Local\Programs\Python\Python311\Lib\site-packages\telegram\ext\_updater.py", line 320, in polling_action_cb
    updates = await self.bot.get_updates(
              ^^^^^^^^^^^^^^^^^^^^^^^^^^^
  File "C:\Users\malek\AppData\Local\Programs\Python\Python311\Lib\site-packages\telegram\ext\_extbot.py", line 543, in get_updates
    updates = await super().get_updates(
              ^^^^^^^^^^^^^^^^^^^^^^^^^^
  File "C:\Users\malek\AppData\Local\Programs\Python\Python311\Lib\site-packages\telegram\_bot.py", line 381, in decorator
    result = await func(self, *args, **kwargs)  # skipcq: PYL-E1102
             ^^^^^^^^^^^^^^^^^^^^^^^^^^^^^^^^^
  File "C:\Users\malek\AppData\Local\Programs\Python\Python311\Lib\site-packages\telegram\_bot.py", line 3661, in get_updates
    await self._post(
  File "C:\Users\malek\AppData\Local\Programs\Python\Python311\Lib\site-packages\telegram\_bot.py", line 469, in _post
    return await self._do_post(
           ^^^^^^^^^^^^^^^^^^^^
  File "C:\Users\malek\AppData\Local\Programs\Python\Python311\Lib\site-packages\telegram\ext\_extbot.py", line 325, in _do_post
    return await super()._do_post(
           ^^^^^^^^^^^^^^^^^^^^^^^
  File "C:\Users\malek\AppData\Local\Programs\Python\Python311\Lib\site-packages\telegram\_bot.py", line 497, in _do_post
    return await request.post(
           ^^^^^^^^^^^^^^^^^^^
  File "C:\Users\malek\AppData\Local\Programs\Python\Python311\Lib\site-packages\telegram\request\_baserequest.py", line 168, in post
    result = await self._request_wrapper(
             ^^^^^^^^^^^^^^^^^^^^^^^^^^^^
  File "C:\Users\malek\AppData\Local\Programs\Python\Python311\Lib\site-packages\telegram\request\_baserequest.py", line 330, in _request_wrapper
    raise Conflict(message)
telegram.error.Conflict: Conflict: terminated by other getUpdates request; make sure that only one bot instance is running
2025-09-18 15:52:36,371 - telegram.ext.Updater - ERROR - Error while getting Updates: Conflict: terminated by other getUpdates request; make sure that only one bot instance is running
2025-09-18 15:52:36,371 - telegram.ext.Application - ERROR - No error handlers are registered, logging exception.
Traceback (most recent call last):
  File "C:\Users\malek\AppData\Local\Programs\Python\Python311\Lib\site-packages\telegram\ext\_updater.py", line 607, in _network_loop_retry
    if not await action_cb():
           ^^^^^^^^^^^^^^^^^
  File "C:\Users\malek\AppData\Local\Programs\Python\Python311\Lib\site-packages\telegram\ext\_updater.py", line 335, in polling_action_cb
    raise exc
  File "C:\Users\malek\AppData\Local\Programs\Python\Python311\Lib\site-packages\telegram\ext\_updater.py", line 320, in polling_action_cb
    updates = await self.bot.get_updates(
              ^^^^^^^^^^^^^^^^^^^^^^^^^^^
  File "C:\Users\malek\AppData\Local\Programs\Python\Python311\Lib\site-packages\telegram\ext\_extbot.py", line 543, in get_updates
    updates = await super().get_updates(
              ^^^^^^^^^^^^^^^^^^^^^^^^^^
  File "C:\Users\malek\AppData\Local\Programs\Python\Python311\Lib\site-packages\telegram\_bot.py", line 381, in decorator
    result = await func(self, *args, **kwargs)  # skipcq: PYL-E1102
             ^^^^^^^^^^^^^^^^^^^^^^^^^^^^^^^^^
  File "C:\Users\malek\AppData\Local\Programs\Python\Python311\Lib\site-packages\telegram\_bot.py", line 3661, in get_updates
    await self._post(
  File "C:\Users\malek\AppData\Local\Programs\Python\Python311\Lib\site-packages\telegram\_bot.py", line 469, in _post
    return await self._do_post(
           ^^^^^^^^^^^^^^^^^^^^
  File "C:\Users\malek\AppData\Local\Programs\Python\Python311\Lib\site-packages\telegram\ext\_extbot.py", line 325, in _do_post
    return await super()._do_post(
           ^^^^^^^^^^^^^^^^^^^^^^^
  File "C:\Users\malek\AppData\Local\Programs\Python\Python311\Lib\site-packages\telegram\_bot.py", line 497, in _do_post
    return await request.post(
           ^^^^^^^^^^^^^^^^^^^
  File "C:\Users\malek\AppData\Local\Programs\Python\Python311\Lib\site-packages\telegram\request\_baserequest.py", line 168, in post
    result = await self._request_wrapper(
             ^^^^^^^^^^^^^^^^^^^^^^^^^^^^
  File "C:\Users\malek\AppData\Local\Programs\Python\Python311\Lib\site-packages\telegram\request\_baserequest.py", line 330, in _request_wrapper
    raise Conflict(message)
telegram.error.Conflict: Conflict: terminated by other getUpdates request; make sure that only one bot instance is running
2025-09-18 15:52:56,393 - telegram.ext.Updater - ERROR - Error while getting Updates: Conflict: terminated by other getUpdates request; make sure that only one bot instance is running
2025-09-18 15:52:56,393 - telegram.ext.Application - ERROR - No error handlers are registered, logging exception.
Traceback (most recent call last):
  File "C:\Users\malek\AppData\Local\Programs\Python\Python311\Lib\site-packages\telegram\ext\_updater.py", line 607, in _network_loop_retry
    if not await action_cb():
           ^^^^^^^^^^^^^^^^^
  File "C:\Users\malek\AppData\Local\Programs\Python\Python311\Lib\site-packages\telegram\ext\_updater.py", line 335, in polling_action_cb
    raise exc
  File "C:\Users\malek\AppData\Local\Programs\Python\Python311\Lib\site-packages\telegram\ext\_updater.py", line 320, in polling_action_cb
    updates = await self.bot.get_updates(
              ^^^^^^^^^^^^^^^^^^^^^^^^^^^
  File "C:\Users\malek\AppData\Local\Programs\Python\Python311\Lib\site-packages\telegram\ext\_extbot.py", line 543, in get_updates
    updates = await super().get_updates(
              ^^^^^^^^^^^^^^^^^^^^^^^^^^
  File "C:\Users\malek\AppData\Local\Programs\Python\Python311\Lib\site-packages\telegram\_bot.py", line 381, in decorator
    result = await func(self, *args, **kwargs)  # skipcq: PYL-E1102
             ^^^^^^^^^^^^^^^^^^^^^^^^^^^^^^^^^
  File "C:\Users\malek\AppData\Local\Programs\Python\Python311\Lib\site-packages\telegram\_bot.py", line 3661, in get_updates
    await self._post(
  File "C:\Users\malek\AppData\Local\Programs\Python\Python311\Lib\site-packages\telegram\_bot.py", line 469, in _post
    return await self._do_post(
           ^^^^^^^^^^^^^^^^^^^^
  File "C:\Users\malek\AppData\Local\Programs\Python\Python311\Lib\site-packages\telegram\ext\_extbot.py", line 325, in _do_post
    return await super()._do_post(
           ^^^^^^^^^^^^^^^^^^^^^^^
  File "C:\Users\malek\AppData\Local\Programs\Python\Python311\Lib\site-packages\telegram\_bot.py", line 497, in _do_post
    return await request.post(
           ^^^^^^^^^^^^^^^^^^^
  File "C:\Users\malek\AppData\Local\Programs\Python\Python311\Lib\site-packages\telegram\request\_baserequest.py", line 168, in post
    result = await self._request_wrapper(
             ^^^^^^^^^^^^^^^^^^^^^^^^^^^^
  File "C:\Users\malek\AppData\Local\Programs\Python\Python311\Lib\site-packages\telegram\request\_baserequest.py", line 330, in _request_wrapper
    raise Conflict(message)
telegram.error.Conflict: Conflict: terminated by other getUpdates request; make sure that only one bot instance is running
2025-09-18 15:53:23,540 - telegram.ext.Updater - ERROR - Error while getting Updates: Conflict: terminated by other getUpdates request; make sure that only one bot instance is running
2025-09-18 15:53:23,540 - telegram.ext.Application - ERROR - No error handlers are registered, logging exception.
Traceback (most recent call last):
  File "C:\Users\malek\AppData\Local\Programs\Python\Python311\Lib\site-packages\telegram\ext\_updater.py", line 607, in _network_loop_retry
    if not await action_cb():
           ^^^^^^^^^^^^^^^^^
  File "C:\Users\malek\AppData\Local\Programs\Python\Python311\Lib\site-packages\telegram\ext\_updater.py", line 335, in polling_action_cb
    raise exc
  File "C:\Users\malek\AppData\Local\Programs\Python\Python311\Lib\site-packages\telegram\ext\_updater.py", line 320, in polling_action_cb
    updates = await self.bot.get_updates(
              ^^^^^^^^^^^^^^^^^^^^^^^^^^^
  File "C:\Users\malek\AppData\Local\Programs\Python\Python311\Lib\site-packages\telegram\ext\_extbot.py", line 543, in get_updates
    updates = await super().get_updates(
              ^^^^^^^^^^^^^^^^^^^^^^^^^^
  File "C:\Users\malek\AppData\Local\Programs\Python\Python311\Lib\site-packages\telegram\_bot.py", line 381, in decorator
    result = await func(self, *args, **kwargs)  # skipcq: PYL-E1102
             ^^^^^^^^^^^^^^^^^^^^^^^^^^^^^^^^^
  File "C:\Users\malek\AppData\Local\Programs\Python\Python311\Lib\site-packages\telegram\_bot.py", line 3661, in get_updates
    await self._post(
  File "C:\Users\malek\AppData\Local\Programs\Python\Python311\Lib\site-packages\telegram\_bot.py", line 469, in _post
    return await self._do_post(
           ^^^^^^^^^^^^^^^^^^^^
  File "C:\Users\malek\AppData\Local\Programs\Python\Python311\Lib\site-packages\telegram\ext\_extbot.py", line 325, in _do_post
    return await super()._do_post(
           ^^^^^^^^^^^^^^^^^^^^^^^
  File "C:\Users\malek\AppData\Local\Programs\Python\Python311\Lib\site-packages\telegram\_bot.py", line 497, in _do_post
    return await request.post(
           ^^^^^^^^^^^^^^^^^^^
  File "C:\Users\malek\AppData\Local\Programs\Python\Python311\Lib\site-packages\telegram\request\_baserequest.py", line 168, in post
    result = await self._request_wrapper(
             ^^^^^^^^^^^^^^^^^^^^^^^^^^^^
  File "C:\Users\malek\AppData\Local\Programs\Python\Python311\Lib\site-packages\telegram\request\_baserequest.py", line 330, in _request_wrapper
    raise Conflict(message)
telegram.error.Conflict: Conflict: terminated by other getUpdates request; make sure that only one bot instance is running
2025-09-18 15:58:24,518 - telegram.ext.Updater - ERROR - Error while getting Updates: Conflict: terminated by other getUpdates request; make sure that only one bot instance is running
2025-09-18 15:58:24,519 - telegram.ext.Application - ERROR - No error handlers are registered, logging exception.
Traceback (most recent call last):
  File "C:\Users\malek\AppData\Local\Programs\Python\Python311\Lib\site-packages\telegram\ext\_updater.py", line 607, in _network_loop_retry
    if not await action_cb():
           ^^^^^^^^^^^^^^^^^
  File "C:\Users\malek\AppData\Local\Programs\Python\Python311\Lib\site-packages\telegram\ext\_updater.py", line 335, in polling_action_cb
    raise exc
  File "C:\Users\malek\AppData\Local\Programs\Python\Python311\Lib\site-packages\telegram\ext\_updater.py", line 320, in polling_action_cb
    updates = await self.bot.get_updates(
              ^^^^^^^^^^^^^^^^^^^^^^^^^^^
  File "C:\Users\malek\AppData\Local\Programs\Python\Python311\Lib\site-packages\telegram\ext\_extbot.py", line 543, in get_updates
    updates = await super().get_updates(
              ^^^^^^^^^^^^^^^^^^^^^^^^^^
  File "C:\Users\malek\AppData\Local\Programs\Python\Python311\Lib\site-packages\telegram\_bot.py", line 381, in decorator
    result = await func(self, *args, **kwargs)  # skipcq: PYL-E1102
             ^^^^^^^^^^^^^^^^^^^^^^^^^^^^^^^^^
  File "C:\Users\malek\AppData\Local\Programs\Python\Python311\Lib\site-packages\telegram\_bot.py", line 3661, in get_updates
    await self._post(
  File "C:\Users\malek\AppData\Local\Programs\Python\Python311\Lib\site-packages\telegram\_bot.py", line 469, in _post
    return await self._do_post(
           ^^^^^^^^^^^^^^^^^^^^
  File "C:\Users\malek\AppData\Local\Programs\Python\Python311\Lib\site-packages\telegram\ext\_extbot.py", line 325, in _do_post
    return await super()._do_post(
           ^^^^^^^^^^^^^^^^^^^^^^^
  File "C:\Users\malek\AppData\Local\Programs\Python\Python311\Lib\site-packages\telegram\_bot.py", line 497, in _do_post
    return await request.post(
           ^^^^^^^^^^^^^^^^^^^
  File "C:\Users\malek\AppData\Local\Programs\Python\Python311\Lib\site-packages\telegram\request\_baserequest.py", line 168, in post
    result = await self._request_wrapper(
             ^^^^^^^^^^^^^^^^^^^^^^^^^^^^
  File "C:\Users\malek\AppData\Local\Programs\Python\Python311\Lib\site-packages\telegram\request\_baserequest.py", line 330, in _request_wrapper
    raise Conflict(message)
telegram.error.Conflict: Conflict: terminated by other getUpdates request; make sure that only one bot instance is running
2025-09-18 15:58:54,465 - telegram.ext.Updater - ERROR - Error while getting Updates: Conflict: terminated by other getUpdates request; make sure that only one bot instance is running
2025-09-18 15:58:54,465 - telegram.ext.Application - ERROR - No error handlers are registered, logging exception.
Traceback (most recent call last):
  File "C:\Users\malek\AppData\Local\Programs\Python\Python311\Lib\site-packages\telegram\ext\_updater.py", line 607, in _network_loop_retry
    if not await action_cb():
           ^^^^^^^^^^^^^^^^^
  File "C:\Users\malek\AppData\Local\Programs\Python\Python311\Lib\site-packages\telegram\ext\_updater.py", line 335, in polling_action_cb
    raise exc
  File "C:\Users\malek\AppData\Local\Programs\Python\Python311\Lib\site-packages\telegram\ext\_updater.py", line 320, in polling_action_cb
    updates = await self.bot.get_updates(
              ^^^^^^^^^^^^^^^^^^^^^^^^^^^
  File "C:\Users\malek\AppData\Local\Programs\Python\Python311\Lib\site-packages\telegram\ext\_extbot.py", line 543, in get_updates
    updates = await super().get_updates(
              ^^^^^^^^^^^^^^^^^^^^^^^^^^
  File "C:\Users\malek\AppData\Local\Programs\Python\Python311\Lib\site-packages\telegram\_bot.py", line 381, in decorator
    result = await func(self, *args, **kwargs)  # skipcq: PYL-E1102
             ^^^^^^^^^^^^^^^^^^^^^^^^^^^^^^^^^
  File "C:\Users\malek\AppData\Local\Programs\Python\Python311\Lib\site-packages\telegram\_bot.py", line 3661, in get_updates
    await self._post(
  File "C:\Users\malek\AppData\Local\Programs\Python\Python311\Lib\site-packages\telegram\_bot.py", line 469, in _post
    return await self._do_post(
           ^^^^^^^^^^^^^^^^^^^^
  File "C:\Users\malek\AppData\Local\Programs\Python\Python311\Lib\site-packages\telegram\ext\_extbot.py", line 325, in _do_post
    return await super()._do_post(
           ^^^^^^^^^^^^^^^^^^^^^^^
  File "C:\Users\malek\AppData\Local\Programs\Python\Python311\Lib\site-packages\telegram\_bot.py", line 497, in _do_post
    return await request.post(
           ^^^^^^^^^^^^^^^^^^^
  File "C:\Users\malek\AppData\Local\Programs\Python\Python311\Lib\site-packages\telegram\request\_baserequest.py", line 168, in post
    result = await self._request_wrapper(
             ^^^^^^^^^^^^^^^^^^^^^^^^^^^^
  File "C:\Users\malek\AppData\Local\Programs\Python\Python311\Lib\site-packages\telegram\request\_baserequest.py", line 330, in _request_wrapper
    raise Conflict(message)
telegram.error.Conflict: Conflict: terminated by other getUpdates request; make sure that only one bot instance is running
2025-09-18 15:59:00,327 - telegram.ext.Updater - ERROR - Error while getting Updates: Conflict: terminated by other getUpdates request; make sure that only one bot instance is running
2025-09-18 15:59:00,327 - telegram.ext.Application - ERROR - No error handlers are registered, logging exception.
Traceback (most recent call last):
  File "C:\Users\malek\AppData\Local\Programs\Python\Python311\Lib\site-packages\telegram\ext\_updater.py", line 607, in _network_loop_retry
    if not await action_cb():
           ^^^^^^^^^^^^^^^^^
  File "C:\Users\malek\AppData\Local\Programs\Python\Python311\Lib\site-packages\telegram\ext\_updater.py", line 335, in polling_action_cb
    raise exc
  File "C:\Users\malek\AppData\Local\Programs\Python\Python311\Lib\site-packages\telegram\ext\_updater.py", line 320, in polling_action_cb
    updates = await self.bot.get_updates(
              ^^^^^^^^^^^^^^^^^^^^^^^^^^^
  File "C:\Users\malek\AppData\Local\Programs\Python\Python311\Lib\site-packages\telegram\ext\_extbot.py", line 543, in get_updates
    updates = await super().get_updates(
              ^^^^^^^^^^^^^^^^^^^^^^^^^^
  File "C:\Users\malek\AppData\Local\Programs\Python\Python311\Lib\site-packages\telegram\_bot.py", line 381, in decorator
    result = await func(self, *args, **kwargs)  # skipcq: PYL-E1102
             ^^^^^^^^^^^^^^^^^^^^^^^^^^^^^^^^^
  File "C:\Users\malek\AppData\Local\Programs\Python\Python311\Lib\site-packages\telegram\_bot.py", line 3661, in get_updates
    await self._post(
  File "C:\Users\malek\AppData\Local\Programs\Python\Python311\Lib\site-packages\telegram\_bot.py", line 469, in _post
    return await self._do_post(
           ^^^^^^^^^^^^^^^^^^^^
  File "C:\Users\malek\AppData\Local\Programs\Python\Python311\Lib\site-packages\telegram\ext\_extbot.py", line 325, in _do_post
    return await super()._do_post(
           ^^^^^^^^^^^^^^^^^^^^^^^
  File "C:\Users\malek\AppData\Local\Programs\Python\Python311\Lib\site-packages\telegram\_bot.py", line 497, in _do_post
    return await request.post(
           ^^^^^^^^^^^^^^^^^^^
  File "C:\Users\malek\AppData\Local\Programs\Python\Python311\Lib\site-packages\telegram\request\_baserequest.py", line 168, in post
    result = await self._request_wrapper(
             ^^^^^^^^^^^^^^^^^^^^^^^^^^^^
  File "C:\Users\malek\AppData\Local\Programs\Python\Python311\Lib\site-packages\telegram\request\_baserequest.py", line 330, in _request_wrapper
    raise Conflict(message)
telegram.error.Conflict: Conflict: terminated by other getUpdates request; make sure that only one bot instance is running
2025-09-18 15:59:08,858 - telegram.ext.Updater - ERROR - Error while getting Updates: Conflict: terminated by other getUpdates request; make sure that only one bot instance is running
2025-09-18 15:59:08,859 - telegram.ext.Application - ERROR - No error handlers are registered, logging exception.
Traceback (most recent call last):
  File "C:\Users\malek\AppData\Local\Programs\Python\Python311\Lib\site-packages\telegram\ext\_updater.py", line 607, in _network_loop_retry
    if not await action_cb():
           ^^^^^^^^^^^^^^^^^
  File "C:\Users\malek\AppData\Local\Programs\Python\Python311\Lib\site-packages\telegram\ext\_updater.py", line 335, in polling_action_cb
    raise exc
  File "C:\Users\malek\AppData\Local\Programs\Python\Python311\Lib\site-packages\telegram\ext\_updater.py", line 320, in polling_action_cb
    updates = await self.bot.get_updates(
              ^^^^^^^^^^^^^^^^^^^^^^^^^^^
  File "C:\Users\malek\AppData\Local\Programs\Python\Python311\Lib\site-packages\telegram\ext\_extbot.py", line 543, in get_updates
    updates = await super().get_updates(
              ^^^^^^^^^^^^^^^^^^^^^^^^^^
  File "C:\Users\malek\AppData\Local\Programs\Python\Python311\Lib\site-packages\telegram\_bot.py", line 381, in decorator
    result = await func(self, *args, **kwargs)  # skipcq: PYL-E1102
             ^^^^^^^^^^^^^^^^^^^^^^^^^^^^^^^^^
  File "C:\Users\malek\AppData\Local\Programs\Python\Python311\Lib\site-packages\telegram\_bot.py", line 3661, in get_updates
    await self._post(
  File "C:\Users\malek\AppData\Local\Programs\Python\Python311\Lib\site-packages\telegram\_bot.py", line 469, in _post
    return await self._do_post(
           ^^^^^^^^^^^^^^^^^^^^
  File "C:\Users\malek\AppData\Local\Programs\Python\Python311\Lib\site-packages\telegram\ext\_extbot.py", line 325, in _do_post
    return await super()._do_post(
           ^^^^^^^^^^^^^^^^^^^^^^^
  File "C:\Users\malek\AppData\Local\Programs\Python\Python311\Lib\site-packages\telegram\_bot.py", line 497, in _do_post
    return await request.post(
           ^^^^^^^^^^^^^^^^^^^
  File "C:\Users\malek\AppData\Local\Programs\Python\Python311\Lib\site-packages\telegram\request\_baserequest.py", line 168, in post
    result = await self._request_wrapper(
             ^^^^^^^^^^^^^^^^^^^^^^^^^^^^
  File "C:\Users\malek\AppData\Local\Programs\Python\Python311\Lib\site-packages\telegram\request\_baserequest.py", line 330, in _request_wrapper
    raise Conflict(message)
telegram.error.Conflict: Conflict: terminated by other getUpdates request; make sure that only one bot instance is running
2025-09-18 15:59:20,269 - telegram.ext.Updater - ERROR - Error while getting Updates: Conflict: terminated by other getUpdates request; make sure that only one bot instance is running
2025-09-18 15:59:20,269 - telegram.ext.Application - ERROR - No error handlers are registered, logging exception.
Traceback (most recent call last):
  File "C:\Users\malek\AppData\Local\Programs\Python\Python311\Lib\site-packages\telegram\ext\_updater.py", line 607, in _network_loop_retry
    if not await action_cb():
           ^^^^^^^^^^^^^^^^^
  File "C:\Users\malek\AppData\Local\Programs\Python\Python311\Lib\site-packages\telegram\ext\_updater.py", line 335, in polling_action_cb
    raise exc
  File "C:\Users\malek\AppData\Local\Programs\Python\Python311\Lib\site-packages\telegram\ext\_updater.py", line 320, in polling_action_cb
    updates = await self.bot.get_updates(
              ^^^^^^^^^^^^^^^^^^^^^^^^^^^
  File "C:\Users\malek\AppData\Local\Programs\Python\Python311\Lib\site-packages\telegram\ext\_extbot.py", line 543, in get_updates
    updates = await super().get_updates(
              ^^^^^^^^^^^^^^^^^^^^^^^^^^
  File "C:\Users\malek\AppData\Local\Programs\Python\Python311\Lib\site-packages\telegram\_bot.py", line 381, in decorator
    result = await func(self, *args, **kwargs)  # skipcq: PYL-E1102
             ^^^^^^^^^^^^^^^^^^^^^^^^^^^^^^^^^
  File "C:\Users\malek\AppData\Local\Programs\Python\Python311\Lib\site-packages\telegram\_bot.py", line 3661, in get_updates
    await self._post(
  File "C:\Users\malek\AppData\Local\Programs\Python\Python311\Lib\site-packages\telegram\_bot.py", line 469, in _post
    return await self._do_post(
           ^^^^^^^^^^^^^^^^^^^^
  File "C:\Users\malek\AppData\Local\Programs\Python\Python311\Lib\site-packages\telegram\ext\_extbot.py", line 325, in _do_post
    return await super()._do_post(
           ^^^^^^^^^^^^^^^^^^^^^^^
  File "C:\Users\malek\AppData\Local\Programs\Python\Python311\Lib\site-packages\telegram\_bot.py", line 497, in _do_post
    return await request.post(
           ^^^^^^^^^^^^^^^^^^^
  File "C:\Users\malek\AppData\Local\Programs\Python\Python311\Lib\site-packages\telegram\request\_baserequest.py", line 168, in post
    result = await self._request_wrapper(
             ^^^^^^^^^^^^^^^^^^^^^^^^^^^^
  File "C:\Users\malek\AppData\Local\Programs\Python\Python311\Lib\site-packages\telegram\request\_baserequest.py", line 330, in _request_wrapper
    raise Conflict(message)
telegram.error.Conflict: Conflict: terminated by other getUpdates request; make sure that only one bot instance is running
2025-09-18 15:59:34,193 - telegram.ext.Updater - ERROR - Error while getting Updates: Conflict: terminated by other getUpdates request; make sure that only one bot instance is running
2025-09-18 15:59:34,194 - telegram.ext.Application - ERROR - No error handlers are registered, logging exception.
Traceback (most recent call last):
  File "C:\Users\malek\AppData\Local\Programs\Python\Python311\Lib\site-packages\telegram\ext\_updater.py", line 607, in _network_loop_retry
    if not await action_cb():
           ^^^^^^^^^^^^^^^^^
  File "C:\Users\malek\AppData\Local\Programs\Python\Python311\Lib\site-packages\telegram\ext\_updater.py", line 335, in polling_action_cb
    raise exc
  File "C:\Users\malek\AppData\Local\Programs\Python\Python311\Lib\site-packages\telegram\ext\_updater.py", line 320, in polling_action_cb
    updates = await self.bot.get_updates(
              ^^^^^^^^^^^^^^^^^^^^^^^^^^^
  File "C:\Users\malek\AppData\Local\Programs\Python\Python311\Lib\site-packages\telegram\ext\_extbot.py", line 543, in get_updates
    updates = await super().get_updates(
              ^^^^^^^^^^^^^^^^^^^^^^^^^^
  File "C:\Users\malek\AppData\Local\Programs\Python\Python311\Lib\site-packages\telegram\_bot.py", line 381, in decorator
    result = await func(self, *args, **kwargs)  # skipcq: PYL-E1102
             ^^^^^^^^^^^^^^^^^^^^^^^^^^^^^^^^^
  File "C:\Users\malek\AppData\Local\Programs\Python\Python311\Lib\site-packages\telegram\_bot.py", line 3661, in get_updates
    await self._post(
  File "C:\Users\malek\AppData\Local\Programs\Python\Python311\Lib\site-packages\telegram\_bot.py", line 469, in _post
    return await self._do_post(
           ^^^^^^^^^^^^^^^^^^^^
  File "C:\Users\malek\AppData\Local\Programs\Python\Python311\Lib\site-packages\telegram\ext\_extbot.py", line 325, in _do_post
    return await super()._do_post(
           ^^^^^^^^^^^^^^^^^^^^^^^
  File "C:\Users\malek\AppData\Local\Programs\Python\Python311\Lib\site-packages\telegram\_bot.py", line 497, in _do_post
    return await request.post(
           ^^^^^^^^^^^^^^^^^^^
  File "C:\Users\malek\AppData\Local\Programs\Python\Python311\Lib\site-packages\telegram\request\_baserequest.py", line 168, in post
    result = await self._request_wrapper(
             ^^^^^^^^^^^^^^^^^^^^^^^^^^^^
  File "C:\Users\malek\AppData\Local\Programs\Python\Python311\Lib\site-packages\telegram\request\_baserequest.py", line 330, in _request_wrapper
    raise Conflict(message)
telegram.error.Conflict: Conflict: terminated by other getUpdates request; make sure that only one bot instance is running
2025-09-18 15:59:53,300 - telegram.ext.Updater - ERROR - Error while getting Updates: Conflict: terminated by other getUpdates request; make sure that only one bot instance is running
2025-09-18 15:59:53,300 - telegram.ext.Application - ERROR - No error handlers are registered, logging exception.
Traceback (most recent call last):
  File "C:\Users\malek\AppData\Local\Programs\Python\Python311\Lib\site-packages\telegram\ext\_updater.py", line 607, in _network_loop_retry
    if not await action_cb():
           ^^^^^^^^^^^^^^^^^
  File "C:\Users\malek\AppData\Local\Programs\Python\Python311\Lib\site-packages\telegram\ext\_updater.py", line 335, in polling_action_cb
    raise exc
  File "C:\Users\malek\AppData\Local\Programs\Python\Python311\Lib\site-packages\telegram\ext\_updater.py", line 320, in polling_action_cb
    updates = await self.bot.get_updates(
              ^^^^^^^^^^^^^^^^^^^^^^^^^^^
  File "C:\Users\malek\AppData\Local\Programs\Python\Python311\Lib\site-packages\telegram\ext\_extbot.py", line 543, in get_updates
    updates = await super().get_updates(
              ^^^^^^^^^^^^^^^^^^^^^^^^^^
  File "C:\Users\malek\AppData\Local\Programs\Python\Python311\Lib\site-packages\telegram\_bot.py", line 381, in decorator
    result = await func(self, *args, **kwargs)  # skipcq: PYL-E1102
             ^^^^^^^^^^^^^^^^^^^^^^^^^^^^^^^^^
  File "C:\Users\malek\AppData\Local\Programs\Python\Python311\Lib\site-packages\telegram\_bot.py", line 3661, in get_updates
    await self._post(
  File "C:\Users\malek\AppData\Local\Programs\Python\Python311\Lib\site-packages\telegram\_bot.py", line 469, in _post
    return await self._do_post(
           ^^^^^^^^^^^^^^^^^^^^
  File "C:\Users\malek\AppData\Local\Programs\Python\Python311\Lib\site-packages\telegram\ext\_extbot.py", line 325, in _do_post
    return await super()._do_post(
           ^^^^^^^^^^^^^^^^^^^^^^^
  File "C:\Users\malek\AppData\Local\Programs\Python\Python311\Lib\site-packages\telegram\_bot.py", line 497, in _do_post
    return await request.post(
           ^^^^^^^^^^^^^^^^^^^
  File "C:\Users\malek\AppData\Local\Programs\Python\Python311\Lib\site-packages\telegram\request\_baserequest.py", line 168, in post
    result = await self._request_wrapper(
             ^^^^^^^^^^^^^^^^^^^^^^^^^^^^
  File "C:\Users\malek\AppData\Local\Programs\Python\Python311\Lib\site-packages\telegram\request\_baserequest.py", line 330, in _request_wrapper
    raise Conflict(message)
telegram.error.Conflict: Conflict: terminated by other getUpdates request; make sure that only one bot instance is running
2025-09-18 16:00:18,524 - telegram.ext.Updater - ERROR - Error while getting Updates: Conflict: terminated by other getUpdates request; make sure that only one bot instance is running
2025-09-18 16:00:18,524 - telegram.ext.Application - ERROR - No error handlers are registered, logging exception.
Traceback (most recent call last):
  File "C:\Users\malek\AppData\Local\Programs\Python\Python311\Lib\site-packages\telegram\ext\_updater.py", line 607, in _network_loop_retry
    if not await action_cb():
           ^^^^^^^^^^^^^^^^^
  File "C:\Users\malek\AppData\Local\Programs\Python\Python311\Lib\site-packages\telegram\ext\_updater.py", line 335, in polling_action_cb
    raise exc
  File "C:\Users\malek\AppData\Local\Programs\Python\Python311\Lib\site-packages\telegram\ext\_updater.py", line 320, in polling_action_cb
    updates = await self.bot.get_updates(
              ^^^^^^^^^^^^^^^^^^^^^^^^^^^
  File "C:\Users\malek\AppData\Local\Programs\Python\Python311\Lib\site-packages\telegram\ext\_extbot.py", line 543, in get_updates
    updates = await super().get_updates(
              ^^^^^^^^^^^^^^^^^^^^^^^^^^
  File "C:\Users\malek\AppData\Local\Programs\Python\Python311\Lib\site-packages\telegram\_bot.py", line 381, in decorator
    result = await func(self, *args, **kwargs)  # skipcq: PYL-E1102
             ^^^^^^^^^^^^^^^^^^^^^^^^^^^^^^^^^
  File "C:\Users\malek\AppData\Local\Programs\Python\Python311\Lib\site-packages\telegram\_bot.py", line 3661, in get_updates
    await self._post(
  File "C:\Users\malek\AppData\Local\Programs\Python\Python311\Lib\site-packages\telegram\_bot.py", line 469, in _post
    return await self._do_post(
           ^^^^^^^^^^^^^^^^^^^^
  File "C:\Users\malek\AppData\Local\Programs\Python\Python311\Lib\site-packages\telegram\ext\_extbot.py", line 325, in _do_post
    return await super()._do_post(
           ^^^^^^^^^^^^^^^^^^^^^^^
  File "C:\Users\malek\AppData\Local\Programs\Python\Python311\Lib\site-packages\telegram\_bot.py", line 497, in _do_post
    return await request.post(
           ^^^^^^^^^^^^^^^^^^^
  File "C:\Users\malek\AppData\Local\Programs\Python\Python311\Lib\site-packages\telegram\request\_baserequest.py", line 168, in post
    result = await self._request_wrapper(
             ^^^^^^^^^^^^^^^^^^^^^^^^^^^^
  File "C:\Users\malek\AppData\Local\Programs\Python\Python311\Lib\site-packages\telegram\request\_baserequest.py", line 330, in _request_wrapper
    raise Conflict(message)
telegram.error.Conflict: Conflict: terminated by other getUpdates request; make sure that only one bot instance is running
2025-09-18 16:00:49,724 - telegram.ext.Updater - ERROR - Error while getting Updates: Conflict: terminated by other getUpdates request; make sure that only one bot instance is running
2025-09-18 16:00:49,724 - telegram.ext.Application - ERROR - No error handlers are registered, logging exception.
Traceback (most recent call last):
  File "C:\Users\malek\AppData\Local\Programs\Python\Python311\Lib\site-packages\telegram\ext\_updater.py", line 607, in _network_loop_retry
    if not await action_cb():
           ^^^^^^^^^^^^^^^^^
  File "C:\Users\malek\AppData\Local\Programs\Python\Python311\Lib\site-packages\telegram\ext\_updater.py", line 335, in polling_action_cb
    raise exc
  File "C:\Users\malek\AppData\Local\Programs\Python\Python311\Lib\site-packages\telegram\ext\_updater.py", line 320, in polling_action_cb
    updates = await self.bot.get_updates(
              ^^^^^^^^^^^^^^^^^^^^^^^^^^^
  File "C:\Users\malek\AppData\Local\Programs\Python\Python311\Lib\site-packages\telegram\ext\_extbot.py", line 543, in get_updates
    updates = await super().get_updates(
              ^^^^^^^^^^^^^^^^^^^^^^^^^^
  File "C:\Users\malek\AppData\Local\Programs\Python\Python311\Lib\site-packages\telegram\_bot.py", line 381, in decorator
    result = await func(self, *args, **kwargs)  # skipcq: PYL-E1102
             ^^^^^^^^^^^^^^^^^^^^^^^^^^^^^^^^^
  File "C:\Users\malek\AppData\Local\Programs\Python\Python311\Lib\site-packages\telegram\_bot.py", line 3661, in get_updates
    await self._post(
  File "C:\Users\malek\AppData\Local\Programs\Python\Python311\Lib\site-packages\telegram\_bot.py", line 469, in _post
    return await self._do_post(
           ^^^^^^^^^^^^^^^^^^^^
  File "C:\Users\malek\AppData\Local\Programs\Python\Python311\Lib\site-packages\telegram\ext\_extbot.py", line 325, in _do_post
    return await super()._do_post(
           ^^^^^^^^^^^^^^^^^^^^^^^
  File "C:\Users\malek\AppData\Local\Programs\Python\Python311\Lib\site-packages\telegram\_bot.py", line 497, in _do_post
    return await request.post(
           ^^^^^^^^^^^^^^^^^^^
  File "C:\Users\malek\AppData\Local\Programs\Python\Python311\Lib\site-packages\telegram\request\_baserequest.py", line 168, in post
    result = await self._request_wrapper(
             ^^^^^^^^^^^^^^^^^^^^^^^^^^^^
  File "C:\Users\malek\AppData\Local\Programs\Python\Python311\Lib\site-packages\telegram\request\_baserequest.py", line 330, in _request_wrapper
    raise Conflict(message)
telegram.error.Conflict: Conflict: terminated by other getUpdates request; make sure that only one bot instance is running
2025-09-18 16:01:27,264 - telegram.ext.Updater - ERROR - Error while getting Updates: Conflict: terminated by other getUpdates request; make sure that only one bot instance is running
2025-09-18 16:01:27,264 - telegram.ext.Application - ERROR - No error handlers are registered, logging exception.
Traceback (most recent call last):
  File "C:\Users\malek\AppData\Local\Programs\Python\Python311\Lib\site-packages\telegram\ext\_updater.py", line 607, in _network_loop_retry
    if not await action_cb():
           ^^^^^^^^^^^^^^^^^
  File "C:\Users\malek\AppData\Local\Programs\Python\Python311\Lib\site-packages\telegram\ext\_updater.py", line 335, in polling_action_cb
    raise exc
  File "C:\Users\malek\AppData\Local\Programs\Python\Python311\Lib\site-packages\telegram\ext\_updater.py", line 320, in polling_action_cb
    updates = await self.bot.get_updates(
              ^^^^^^^^^^^^^^^^^^^^^^^^^^^
  File "C:\Users\malek\AppData\Local\Programs\Python\Python311\Lib\site-packages\telegram\ext\_extbot.py", line 543, in get_updates
    updates = await super().get_updates(
              ^^^^^^^^^^^^^^^^^^^^^^^^^^
  File "C:\Users\malek\AppData\Local\Programs\Python\Python311\Lib\site-packages\telegram\_bot.py", line 381, in decorator
    result = await func(self, *args, **kwargs)  # skipcq: PYL-E1102
             ^^^^^^^^^^^^^^^^^^^^^^^^^^^^^^^^^
  File "C:\Users\malek\AppData\Local\Programs\Python\Python311\Lib\site-packages\telegram\_bot.py", line 3661, in get_updates
    await self._post(
  File "C:\Users\malek\AppData\Local\Programs\Python\Python311\Lib\site-packages\telegram\_bot.py", line 469, in _post
    return await self._do_post(
           ^^^^^^^^^^^^^^^^^^^^
  File "C:\Users\malek\AppData\Local\Programs\Python\Python311\Lib\site-packages\telegram\ext\_extbot.py", line 325, in _do_post
    return await super()._do_post(
           ^^^^^^^^^^^^^^^^^^^^^^^
  File "C:\Users\malek\AppData\Local\Programs\Python\Python311\Lib\site-packages\telegram\_bot.py", line 497, in _do_post
    return await request.post(
           ^^^^^^^^^^^^^^^^^^^
  File "C:\Users\malek\AppData\Local\Programs\Python\Python311\Lib\site-packages\telegram\request\_baserequest.py", line 168, in post
    result = await self._request_wrapper(
             ^^^^^^^^^^^^^^^^^^^^^^^^^^^^
  File "C:\Users\malek\AppData\Local\Programs\Python\Python311\Lib\site-packages\telegram\request\_baserequest.py", line 330, in _request_wrapper
    raise Conflict(message)
telegram.error.Conflict: Conflict: terminated by other getUpdates request; make sure that only one bot instance is running
2025-09-18 16:02:03,368 - telegram.ext.Updater - ERROR - Error while getting Updates: Conflict: terminated by other getUpdates request; make sure that only one bot instance is running
2025-09-18 16:02:03,368 - telegram.ext.Application - ERROR - No error handlers are registered, logging exception.
Traceback (most recent call last):
  File "C:\Users\malek\AppData\Local\Programs\Python\Python311\Lib\site-packages\telegram\ext\_updater.py", line 607, in _network_loop_retry
    if not await action_cb():
           ^^^^^^^^^^^^^^^^^
  File "C:\Users\malek\AppData\Local\Programs\Python\Python311\Lib\site-packages\telegram\ext\_updater.py", line 335, in polling_action_cb
    raise exc
  File "C:\Users\malek\AppData\Local\Programs\Python\Python311\Lib\site-packages\telegram\ext\_updater.py", line 320, in polling_action_cb
    updates = await self.bot.get_updates(
              ^^^^^^^^^^^^^^^^^^^^^^^^^^^
  File "C:\Users\malek\AppData\Local\Programs\Python\Python311\Lib\site-packages\telegram\ext\_extbot.py", line 543, in get_updates
    updates = await super().get_updates(
              ^^^^^^^^^^^^^^^^^^^^^^^^^^
  File "C:\Users\malek\AppData\Local\Programs\Python\Python311\Lib\site-packages\telegram\_bot.py", line 381, in decorator
    result = await func(self, *args, **kwargs)  # skipcq: PYL-E1102
             ^^^^^^^^^^^^^^^^^^^^^^^^^^^^^^^^^
  File "C:\Users\malek\AppData\Local\Programs\Python\Python311\Lib\site-packages\telegram\_bot.py", line 3661, in get_updates
    await self._post(
  File "C:\Users\malek\AppData\Local\Programs\Python\Python311\Lib\site-packages\telegram\_bot.py", line 469, in _post
    return await self._do_post(
           ^^^^^^^^^^^^^^^^^^^^
  File "C:\Users\malek\AppData\Local\Programs\Python\Python311\Lib\site-packages\telegram\ext\_extbot.py", line 325, in _do_post
    return await super()._do_post(
           ^^^^^^^^^^^^^^^^^^^^^^^
  File "C:\Users\malek\AppData\Local\Programs\Python\Python311\Lib\site-packages\telegram\_bot.py", line 497, in _do_post
    return await request.post(
           ^^^^^^^^^^^^^^^^^^^
  File "C:\Users\malek\AppData\Local\Programs\Python\Python311\Lib\site-packages\telegram\request\_baserequest.py", line 168, in post
    result = await self._request_wrapper(
             ^^^^^^^^^^^^^^^^^^^^^^^^^^^^
  File "C:\Users\malek\AppData\Local\Programs\Python\Python311\Lib\site-packages\telegram\request\_baserequest.py", line 330, in _request_wrapper
    raise Conflict(message)
telegram.error.Conflict: Conflict: terminated by other getUpdates request; make sure that only one bot instance is running
2025-09-18 16:02:37,970 - telegram.ext.Updater - ERROR - Error while getting Updates: Conflict: terminated by other getUpdates request; make sure that only one bot instance is running
2025-09-18 16:02:37,974 - telegram.ext.Application - ERROR - No error handlers are registered, logging exception.
Traceback (most recent call last):
  File "C:\Users\malek\AppData\Local\Programs\Python\Python311\Lib\site-packages\telegram\ext\_updater.py", line 607, in _network_loop_retry
    if not await action_cb():
           ^^^^^^^^^^^^^^^^^
  File "C:\Users\malek\AppData\Local\Programs\Python\Python311\Lib\site-packages\telegram\ext\_updater.py", line 335, in polling_action_cb
    raise exc
  File "C:\Users\malek\AppData\Local\Programs\Python\Python311\Lib\site-packages\telegram\ext\_updater.py", line 320, in polling_action_cb
    updates = await self.bot.get_updates(
              ^^^^^^^^^^^^^^^^^^^^^^^^^^^
  File "C:\Users\malek\AppData\Local\Programs\Python\Python311\Lib\site-packages\telegram\ext\_extbot.py", line 543, in get_updates
    updates = await super().get_updates(
              ^^^^^^^^^^^^^^^^^^^^^^^^^^
  File "C:\Users\malek\AppData\Local\Programs\Python\Python311\Lib\site-packages\telegram\_bot.py", line 381, in decorator
    result = await func(self, *args, **kwargs)  # skipcq: PYL-E1102
             ^^^^^^^^^^^^^^^^^^^^^^^^^^^^^^^^^
  File "C:\Users\malek\AppData\Local\Programs\Python\Python311\Lib\site-packages\telegram\_bot.py", line 3661, in get_updates
    await self._post(
  File "C:\Users\malek\AppData\Local\Programs\Python\Python311\Lib\site-packages\telegram\_bot.py", line 469, in _post
    return await self._do_post(
           ^^^^^^^^^^^^^^^^^^^^
  File "C:\Users\malek\AppData\Local\Programs\Python\Python311\Lib\site-packages\telegram\ext\_extbot.py", line 325, in _do_post
    return await super()._do_post(
           ^^^^^^^^^^^^^^^^^^^^^^^
  File "C:\Users\malek\AppData\Local\Programs\Python\Python311\Lib\site-packages\telegram\_bot.py", line 497, in _do_post
    return await request.post(
           ^^^^^^^^^^^^^^^^^^^
  File "C:\Users\malek\AppData\Local\Programs\Python\Python311\Lib\site-packages\telegram\request\_baserequest.py", line 168, in post
    result = await self._request_wrapper(
             ^^^^^^^^^^^^^^^^^^^^^^^^^^^^
  File "C:\Users\malek\AppData\Local\Programs\Python\Python311\Lib\site-packages\telegram\request\_baserequest.py", line 330, in _request_wrapper
    raise Conflict(message)
telegram.error.Conflict: Conflict: terminated by other getUpdates request; make sure that only one bot instance is running
2025-09-18 16:03:17,384 - telegram.ext.Updater - ERROR - Error while getting Updates: Conflict: terminated by other getUpdates request; make sure that only one bot instance is running
2025-09-18 16:03:17,384 - telegram.ext.Application - ERROR - No error handlers are registered, logging exception.
Traceback (most recent call last):
  File "C:\Users\malek\AppData\Local\Programs\Python\Python311\Lib\site-packages\telegram\ext\_updater.py", line 607, in _network_loop_retry
    if not await action_cb():
           ^^^^^^^^^^^^^^^^^
  File "C:\Users\malek\AppData\Local\Programs\Python\Python311\Lib\site-packages\telegram\ext\_updater.py", line 335, in polling_action_cb
    raise exc
  File "C:\Users\malek\AppData\Local\Programs\Python\Python311\Lib\site-packages\telegram\ext\_updater.py", line 320, in polling_action_cb
    updates = await self.bot.get_updates(
              ^^^^^^^^^^^^^^^^^^^^^^^^^^^
  File "C:\Users\malek\AppData\Local\Programs\Python\Python311\Lib\site-packages\telegram\ext\_extbot.py", line 543, in get_updates
    updates = await super().get_updates(
              ^^^^^^^^^^^^^^^^^^^^^^^^^^
  File "C:\Users\malek\AppData\Local\Programs\Python\Python311\Lib\site-packages\telegram\_bot.py", line 381, in decorator
    result = await func(self, *args, **kwargs)  # skipcq: PYL-E1102
             ^^^^^^^^^^^^^^^^^^^^^^^^^^^^^^^^^
  File "C:\Users\malek\AppData\Local\Programs\Python\Python311\Lib\site-packages\telegram\_bot.py", line 3661, in get_updates
    await self._post(
  File "C:\Users\malek\AppData\Local\Programs\Python\Python311\Lib\site-packages\telegram\_bot.py", line 469, in _post
    return await self._do_post(
           ^^^^^^^^^^^^^^^^^^^^
  File "C:\Users\malek\AppData\Local\Programs\Python\Python311\Lib\site-packages\telegram\ext\_extbot.py", line 325, in _do_post
    return await super()._do_post(
           ^^^^^^^^^^^^^^^^^^^^^^^
  File "C:\Users\malek\AppData\Local\Programs\Python\Python311\Lib\site-packages\telegram\_bot.py", line 497, in _do_post
    return await request.post(
           ^^^^^^^^^^^^^^^^^^^
  File "C:\Users\malek\AppData\Local\Programs\Python\Python311\Lib\site-packages\telegram\request\_baserequest.py", line 168, in post
    result = await self._request_wrapper(
             ^^^^^^^^^^^^^^^^^^^^^^^^^^^^
  File "C:\Users\malek\AppData\Local\Programs\Python\Python311\Lib\site-packages\telegram\request\_baserequest.py", line 330, in _request_wrapper
    raise Conflict(message)
telegram.error.Conflict: Conflict: terminated by other getUpdates request; make sure that only one bot instance is running
2025-09-18 16:03:57,887 - telegram.ext.Updater - ERROR - Error while getting Updates: Conflict: terminated by other getUpdates request; make sure that only one bot instance is running
2025-09-18 16:03:57,890 - telegram.ext.Application - ERROR - No error handlers are registered, logging exception.
Traceback (most recent call last):
  File "C:\Users\malek\AppData\Local\Programs\Python\Python311\Lib\site-packages\telegram\ext\_updater.py", line 607, in _network_loop_retry
    if not await action_cb():
           ^^^^^^^^^^^^^^^^^
  File "C:\Users\malek\AppData\Local\Programs\Python\Python311\Lib\site-packages\telegram\ext\_updater.py", line 335, in polling_action_cb
    raise exc
  File "C:\Users\malek\AppData\Local\Programs\Python\Python311\Lib\site-packages\telegram\ext\_updater.py", line 320, in polling_action_cb
    updates = await self.bot.get_updates(
              ^^^^^^^^^^^^^^^^^^^^^^^^^^^
  File "C:\Users\malek\AppData\Local\Programs\Python\Python311\Lib\site-packages\telegram\ext\_extbot.py", line 543, in get_updates
    updates = await super().get_updates(
              ^^^^^^^^^^^^^^^^^^^^^^^^^^
  File "C:\Users\malek\AppData\Local\Programs\Python\Python311\Lib\site-packages\telegram\_bot.py", line 381, in decorator
    result = await func(self, *args, **kwargs)  # skipcq: PYL-E1102
             ^^^^^^^^^^^^^^^^^^^^^^^^^^^^^^^^^
  File "C:\Users\malek\AppData\Local\Programs\Python\Python311\Lib\site-packages\telegram\_bot.py", line 3661, in get_updates
    await self._post(
  File "C:\Users\malek\AppData\Local\Programs\Python\Python311\Lib\site-packages\telegram\_bot.py", line 469, in _post
    return await self._do_post(
           ^^^^^^^^^^^^^^^^^^^^
  File "C:\Users\malek\AppData\Local\Programs\Python\Python311\Lib\site-packages\telegram\ext\_extbot.py", line 325, in _do_post
    return await super()._do_post(
           ^^^^^^^^^^^^^^^^^^^^^^^
  File "C:\Users\malek\AppData\Local\Programs\Python\Python311\Lib\site-packages\telegram\_bot.py", line 497, in _do_post
    return await request.post(
           ^^^^^^^^^^^^^^^^^^^
  File "C:\Users\malek\AppData\Local\Programs\Python\Python311\Lib\site-packages\telegram\request\_baserequest.py", line 168, in post
    result = await self._request_wrapper(
             ^^^^^^^^^^^^^^^^^^^^^^^^^^^^
  File "C:\Users\malek\AppData\Local\Programs\Python\Python311\Lib\site-packages\telegram\request\_baserequest.py", line 330, in _request_wrapper
    raise Conflict(message)
telegram.error.Conflict: Conflict: terminated by other getUpdates request; make sure that only one bot instance is running
2025-09-18 16:04:46,521 - telegram.ext.Updater - ERROR - Error while getting Updates: Conflict: terminated by other getUpdates request; make sure that only one bot instance is running
2025-09-18 16:04:46,523 - telegram.ext.Application - ERROR - No error handlers are registered, logging exception.
Traceback (most recent call last):
  File "C:\Users\malek\AppData\Local\Programs\Python\Python311\Lib\site-packages\telegram\ext\_updater.py", line 607, in _network_loop_retry
    if not await action_cb():
           ^^^^^^^^^^^^^^^^^
  File "C:\Users\malek\AppData\Local\Programs\Python\Python311\Lib\site-packages\telegram\ext\_updater.py", line 335, in polling_action_cb
    raise exc
  File "C:\Users\malek\AppData\Local\Programs\Python\Python311\Lib\site-packages\telegram\ext\_updater.py", line 320, in polling_action_cb
    updates = await self.bot.get_updates(
              ^^^^^^^^^^^^^^^^^^^^^^^^^^^
  File "C:\Users\malek\AppData\Local\Programs\Python\Python311\Lib\site-packages\telegram\ext\_extbot.py", line 543, in get_updates
    updates = await super().get_updates(
              ^^^^^^^^^^^^^^^^^^^^^^^^^^
  File "C:\Users\malek\AppData\Local\Programs\Python\Python311\Lib\site-packages\telegram\_bot.py", line 381, in decorator
    result = await func(self, *args, **kwargs)  # skipcq: PYL-E1102
             ^^^^^^^^^^^^^^^^^^^^^^^^^^^^^^^^^
  File "C:\Users\malek\AppData\Local\Programs\Python\Python311\Lib\site-packages\telegram\_bot.py", line 3661, in get_updates
    await self._post(
  File "C:\Users\malek\AppData\Local\Programs\Python\Python311\Lib\site-packages\telegram\_bot.py", line 469, in _post
    return await self._do_post(
           ^^^^^^^^^^^^^^^^^^^^
  File "C:\Users\malek\AppData\Local\Programs\Python\Python311\Lib\site-packages\telegram\ext\_extbot.py", line 325, in _do_post
    return await super()._do_post(
           ^^^^^^^^^^^^^^^^^^^^^^^
  File "C:\Users\malek\AppData\Local\Programs\Python\Python311\Lib\site-packages\telegram\_bot.py", line 497, in _do_post
    return await request.post(
           ^^^^^^^^^^^^^^^^^^^
  File "C:\Users\malek\AppData\Local\Programs\Python\Python311\Lib\site-packages\telegram\request\_baserequest.py", line 168, in post
    result = await self._request_wrapper(
             ^^^^^^^^^^^^^^^^^^^^^^^^^^^^
  File "C:\Users\malek\AppData\Local\Programs\Python\Python311\Lib\site-packages\telegram\request\_baserequest.py", line 330, in _request_wrapper
    raise Conflict(message)
telegram.error.Conflict: Conflict: terminated by other getUpdates request; make sure that only one bot instance is running
2025-09-18 16:05:31,165 - telegram.ext.Updater - ERROR - Error while getting Updates: Conflict: terminated by other getUpdates request; make sure that only one bot instance is running
2025-09-18 16:05:31,165 - telegram.ext.Application - ERROR - No error handlers are registered, logging exception.
Traceback (most recent call last):
  File "C:\Users\malek\AppData\Local\Programs\Python\Python311\Lib\site-packages\telegram\ext\_updater.py", line 607, in _network_loop_retry
    if not await action_cb():
           ^^^^^^^^^^^^^^^^^
  File "C:\Users\malek\AppData\Local\Programs\Python\Python311\Lib\site-packages\telegram\ext\_updater.py", line 335, in polling_action_cb
    raise exc
  File "C:\Users\malek\AppData\Local\Programs\Python\Python311\Lib\site-packages\telegram\ext\_updater.py", line 320, in polling_action_cb
    updates = await self.bot.get_updates(
              ^^^^^^^^^^^^^^^^^^^^^^^^^^^
  File "C:\Users\malek\AppData\Local\Programs\Python\Python311\Lib\site-packages\telegram\ext\_extbot.py", line 543, in get_updates
    updates = await super().get_updates(
              ^^^^^^^^^^^^^^^^^^^^^^^^^^
  File "C:\Users\malek\AppData\Local\Programs\Python\Python311\Lib\site-packages\telegram\_bot.py", line 381, in decorator
    result = await func(self, *args, **kwargs)  # skipcq: PYL-E1102
             ^^^^^^^^^^^^^^^^^^^^^^^^^^^^^^^^^
  File "C:\Users\malek\AppData\Local\Programs\Python\Python311\Lib\site-packages\telegram\_bot.py", line 3661, in get_updates
    await self._post(
  File "C:\Users\malek\AppData\Local\Programs\Python\Python311\Lib\site-packages\telegram\_bot.py", line 469, in _post
    return await self._do_post(
           ^^^^^^^^^^^^^^^^^^^^
  File "C:\Users\malek\AppData\Local\Programs\Python\Python311\Lib\site-packages\telegram\ext\_extbot.py", line 325, in _do_post
    return await super()._do_post(
           ^^^^^^^^^^^^^^^^^^^^^^^
  File "C:\Users\malek\AppData\Local\Programs\Python\Python311\Lib\site-packages\telegram\_bot.py", line 497, in _do_post
    return await request.post(
           ^^^^^^^^^^^^^^^^^^^
  File "C:\Users\malek\AppData\Local\Programs\Python\Python311\Lib\site-packages\telegram\request\_baserequest.py", line 168, in post
    result = await self._request_wrapper(
             ^^^^^^^^^^^^^^^^^^^^^^^^^^^^
  File "C:\Users\malek\AppData\Local\Programs\Python\Python311\Lib\site-packages\telegram\request\_baserequest.py", line 330, in _request_wrapper
    raise Conflict(message)
telegram.error.Conflict: Conflict: terminated by other getUpdates request; make sure that only one bot instance is running
2025-09-18 16:06:19,174 - telegram.ext.Updater - ERROR - Error while getting Updates: Conflict: terminated by other getUpdates request; make sure that only one bot instance is running
2025-09-18 16:06:19,187 - telegram.ext.Application - ERROR - No error handlers are registered, logging exception.
Traceback (most recent call last):
  File "C:\Users\malek\AppData\Local\Programs\Python\Python311\Lib\site-packages\telegram\ext\_updater.py", line 607, in _network_loop_retry
    if not await action_cb():
           ^^^^^^^^^^^^^^^^^
  File "C:\Users\malek\AppData\Local\Programs\Python\Python311\Lib\site-packages\telegram\ext\_updater.py", line 335, in polling_action_cb
    raise exc
  File "C:\Users\malek\AppData\Local\Programs\Python\Python311\Lib\site-packages\telegram\ext\_updater.py", line 320, in polling_action_cb
    updates = await self.bot.get_updates(
              ^^^^^^^^^^^^^^^^^^^^^^^^^^^
  File "C:\Users\malek\AppData\Local\Programs\Python\Python311\Lib\site-packages\telegram\ext\_extbot.py", line 543, in get_updates
    updates = await super().get_updates(
              ^^^^^^^^^^^^^^^^^^^^^^^^^^
  File "C:\Users\malek\AppData\Local\Programs\Python\Python311\Lib\site-packages\telegram\_bot.py", line 381, in decorator
    result = await func(self, *args, **kwargs)  # skipcq: PYL-E1102
             ^^^^^^^^^^^^^^^^^^^^^^^^^^^^^^^^^
  File "C:\Users\malek\AppData\Local\Programs\Python\Python311\Lib\site-packages\telegram\_bot.py", line 3661, in get_updates
    await self._post(
  File "C:\Users\malek\AppData\Local\Programs\Python\Python311\Lib\site-packages\telegram\_bot.py", line 469, in _post
    return await self._do_post(
           ^^^^^^^^^^^^^^^^^^^^
  File "C:\Users\malek\AppData\Local\Programs\Python\Python311\Lib\site-packages\telegram\ext\_extbot.py", line 325, in _do_post
    return await super()._do_post(
           ^^^^^^^^^^^^^^^^^^^^^^^
  File "C:\Users\malek\AppData\Local\Programs\Python\Python311\Lib\site-packages\telegram\_bot.py", line 497, in _do_post
    return await request.post(
           ^^^^^^^^^^^^^^^^^^^
  File "C:\Users\malek\AppData\Local\Programs\Python\Python311\Lib\site-packages\telegram\request\_baserequest.py", line 168, in post
    result = await self._request_wrapper(
             ^^^^^^^^^^^^^^^^^^^^^^^^^^^^
  File "C:\Users\malek\AppData\Local\Programs\Python\Python311\Lib\site-packages\telegram\request\_baserequest.py", line 330, in _request_wrapper
    raise Conflict(message)
telegram.error.Conflict: Conflict: terminated by other getUpdates request; make sure that only one bot instance is running
2025-09-18 16:07:03,815 - telegram.ext.Updater - ERROR - Error while getting Updates: Conflict: terminated by other getUpdates request; make sure that only one bot instance is running
2025-09-18 16:07:03,815 - telegram.ext.Application - ERROR - No error handlers are registered, logging exception.
Traceback (most recent call last):
  File "C:\Users\malek\AppData\Local\Programs\Python\Python311\Lib\site-packages\telegram\ext\_updater.py", line 607, in _network_loop_retry
    if not await action_cb():
           ^^^^^^^^^^^^^^^^^
  File "C:\Users\malek\AppData\Local\Programs\Python\Python311\Lib\site-packages\telegram\ext\_updater.py", line 335, in polling_action_cb
    raise exc
  File "C:\Users\malek\AppData\Local\Programs\Python\Python311\Lib\site-packages\telegram\ext\_updater.py", line 320, in polling_action_cb
    updates = await self.bot.get_updates(
              ^^^^^^^^^^^^^^^^^^^^^^^^^^^
  File "C:\Users\malek\AppData\Local\Programs\Python\Python311\Lib\site-packages\telegram\ext\_extbot.py", line 543, in get_updates
    updates = await super().get_updates(
              ^^^^^^^^^^^^^^^^^^^^^^^^^^
  File "C:\Users\malek\AppData\Local\Programs\Python\Python311\Lib\site-packages\telegram\_bot.py", line 381, in decorator
    result = await func(self, *args, **kwargs)  # skipcq: PYL-E1102
             ^^^^^^^^^^^^^^^^^^^^^^^^^^^^^^^^^
  File "C:\Users\malek\AppData\Local\Programs\Python\Python311\Lib\site-packages\telegram\_bot.py", line 3661, in get_updates
    await self._post(
  File "C:\Users\malek\AppData\Local\Programs\Python\Python311\Lib\site-packages\telegram\_bot.py", line 469, in _post
    return await self._do_post(
           ^^^^^^^^^^^^^^^^^^^^
  File "C:\Users\malek\AppData\Local\Programs\Python\Python311\Lib\site-packages\telegram\ext\_extbot.py", line 325, in _do_post
    return await super()._do_post(
           ^^^^^^^^^^^^^^^^^^^^^^^
  File "C:\Users\malek\AppData\Local\Programs\Python\Python311\Lib\site-packages\telegram\_bot.py", line 497, in _do_post
    return await request.post(
           ^^^^^^^^^^^^^^^^^^^
  File "C:\Users\malek\AppData\Local\Programs\Python\Python311\Lib\site-packages\telegram\request\_baserequest.py", line 168, in post
    result = await self._request_wrapper(
             ^^^^^^^^^^^^^^^^^^^^^^^^^^^^
  File "C:\Users\malek\AppData\Local\Programs\Python\Python311\Lib\site-packages\telegram\request\_baserequest.py", line 330, in _request_wrapper
    raise Conflict(message)
telegram.error.Conflict: Conflict: terminated by other getUpdates request; make sure that only one bot instance is running
2025-09-18 16:07:14,334 - bot - ERROR - Error during shutdown: 'Application' object has no attribute 'stop_running'
2025-09-18 16:07:55,906 - telegram.ext.Updater - ERROR - Error while getting Updates: Conflict: terminated by other getUpdates request; make sure that only one bot instance is running
2025-09-18 16:07:55,906 - telegram.ext.Application - ERROR - No error handlers are registered, logging exception.
Traceback (most recent call last):
  File "C:\Users\malek\AppData\Local\Programs\Python\Python311\Lib\site-packages\telegram\ext\_updater.py", line 607, in _network_loop_retry
    if not await action_cb():
           ^^^^^^^^^^^^^^^^^
  File "C:\Users\malek\AppData\Local\Programs\Python\Python311\Lib\site-packages\telegram\ext\_updater.py", line 335, in polling_action_cb
    raise exc
  File "C:\Users\malek\AppData\Local\Programs\Python\Python311\Lib\site-packages\telegram\ext\_updater.py", line 320, in polling_action_cb
    updates = await self.bot.get_updates(
              ^^^^^^^^^^^^^^^^^^^^^^^^^^^
  File "C:\Users\malek\AppData\Local\Programs\Python\Python311\Lib\site-packages\telegram\ext\_extbot.py", line 543, in get_updates
    updates = await super().get_updates(
              ^^^^^^^^^^^^^^^^^^^^^^^^^^
  File "C:\Users\malek\AppData\Local\Programs\Python\Python311\Lib\site-packages\telegram\_bot.py", line 381, in decorator
    result = await func(self, *args, **kwargs)  # skipcq: PYL-E1102
             ^^^^^^^^^^^^^^^^^^^^^^^^^^^^^^^^^
  File "C:\Users\malek\AppData\Local\Programs\Python\Python311\Lib\site-packages\telegram\_bot.py", line 3661, in get_updates
    await self._post(
  File "C:\Users\malek\AppData\Local\Programs\Python\Python311\Lib\site-packages\telegram\_bot.py", line 469, in _post
    return await self._do_post(
           ^^^^^^^^^^^^^^^^^^^^
  File "C:\Users\malek\AppData\Local\Programs\Python\Python311\Lib\site-packages\telegram\ext\_extbot.py", line 325, in _do_post
    return await super()._do_post(
           ^^^^^^^^^^^^^^^^^^^^^^^
  File "C:\Users\malek\AppData\Local\Programs\Python\Python311\Lib\site-packages\telegram\_bot.py", line 497, in _do_post
    return await request.post(
           ^^^^^^^^^^^^^^^^^^^
  File "C:\Users\malek\AppData\Local\Programs\Python\Python311\Lib\site-packages\telegram\request\_baserequest.py", line 168, in post
    result = await self._request_wrapper(
             ^^^^^^^^^^^^^^^^^^^^^^^^^^^^
  File "C:\Users\malek\AppData\Local\Programs\Python\Python311\Lib\site-packages\telegram\request\_baserequest.py", line 330, in _request_wrapper
    raise Conflict(message)
telegram.error.Conflict: Conflict: terminated by other getUpdates request; make sure that only one bot instance is running
2025-09-18 16:08:03,907 - bot - ERROR - Error during shutdown: 'Application' object has no attribute 'stop_running'
2025-09-18 16:08:15,493 - bot - ERROR - Error during shutdown: 'Application' object has no attribute 'stop_running'
2025-09-18 16:08:16,109 - bot - ERROR - Error during shutdown: 'Application' object has no attribute 'stop_running'
